[/bin/bash] ## This is shankaras1 on #HOSTNAME and job ID 2439935
[/bin/bash] Current working directory: /home/shankaras1/data1/python_files/BLG
[/bin/bash] Running Python script
PROCESSES = 24
omega = 1e-06 entered
omega = 1.77862e-06 entered
omega = 3.16349e-06 entered
omega = 5.62665e-06 entered
omega = 1.00077e-05 entered
omega = 1.77999e-05 entered
omega = 5.63097e-05 entered
omega = 3.16592e-05 entered
omega = 0.000100154 entered
omega = 0.000178135 entered
omega = 0.000316835 entered
omega = 0.00056353 entered
omega = 0.00100231 entered
omega = 0.00317079 entered
omega = 0.00563963 entered
omega = 0.00178272 entered
omega = 0.0100308 entered
omega = 0.0178409 entered
omega = 0.0564396 entered
omega = 0.100385 entered
omega = 0.0317322 entered
omega = 0.178546 entered
omega = 0.317566 entered
omega = 0.564829 entered
/data1/shankaras1/python_files/BLG/v3_RGF_BBG.py:235: IntegrationWarning: The integral is probably divergent, or slowly convergent.
  intlist = [quad(call_int,window[0],window[1],limit=200,epsabs=delta)[0] for window in ranges]
/data1/shankaras1/python_files/BLG/v3_RGF_BBG.py:235: IntegrationWarning: The integral is probably divergent, or slowly convergent.
  intlist = [quad(call_int,window[0],window[1],limit=200,epsabs=delta)[0] for window in ranges]
/data1/shankaras1/python_files/BLG/v3_RGF_BBG.py:235: IntegrationWarning: The integral is probably divergent, or slowly convergent.
  intlist = [quad(call_int,window[0],window[1],limit=200,epsabs=delta)[0] for window in ranges]
/data1/shankaras1/python_files/BLG/v3_RGF_BBG.py:235: IntegrationWarning: The integral is probably divergent, or slowly convergent.
  intlist = [quad(call_int,window[0],window[1],limit=200,epsabs=delta)[0] for window in ranges]
/data1/shankaras1/python_files/BLG/v3_RGF_BBG.py:235: IntegrationWarning: The integral is probably divergent, or slowly convergent.
  intlist = [quad(call_int,window[0],window[1],limit=200,epsabs=delta)[0] for window in ranges]
/data1/shankaras1/python_files/BLG/v3_RGF_BBG.py:235: IntegrationWarning: The integral is probably divergent, or slowly convergent.
  intlist = [quad(call_int,window[0],window[1],limit=200,epsabs=delta)[0] for window in ranges]
/data1/shankaras1/python_files/BLG/v3_RGF_BBG.py:235: IntegrationWarning: The integral is probably divergent, or slowly convergent.
  intlist = [quad(call_int,window[0],window[1],limit=200,epsabs=delta)[0] for window in ranges]
/data1/shankaras1/python_files/BLG/v3_RGF_BBG.py:235: IntegrationWarning: The integral is probably divergent, or slowly convergent.
  intlist = [quad(call_int,window[0],window[1],limit=200,epsabs=delta)[0] for window in ranges]
/data1/shankaras1/python_files/BLG/v3_RGF_BBG.py:235: IntegrationWarning: The integral is probably divergent, or slowly convergent.
  intlist = [quad(call_int,window[0],window[1],limit=200,epsabs=delta)[0] for window in ranges]
omega = 0.0178409 finished in 34.04194279300282 seconds.
omega = 0.0179233 entered
omega = 0.00100231 finished in 34.184007514995756 seconds.
omega = 0.00100693 entered
omega = 0.178546 finished in 34.1989088190021 seconds.
omega = 0.179371 entered
omega = 0.00563963 finished in 34.30747827101732 seconds.
omega = 0.00566567 entered
omega = 0.00178272 finished in 34.366366680013016 seconds.
omega = 0.00179095 entered
omega = 0.00317079 finished in 34.40233881797758 seconds.
omega = 0.00318543 entered
omega = 0.0317322 finished in 34.678563251014566 seconds.
omega = 0.0318787 entered
omega = 0.317566 finished in 34.85162808201858 seconds.
omega = 0.319032 entered
omega = 0.100385 finished in 34.99743605797994 seconds.
omega = 0.100848 entered
omega = 0.0564396 finished in 35.03886361900368 seconds.
omega = 0.0567002 entered
2024-05-09 22:08:05,328 - distributed.worker - ERROR - Timed out during handshake while connecting to tcp://127.0.0.1:39719 after 30 s
Traceback (most recent call last):
  File "/home/shankaras1/.venv/lib/python3.10/site-packages/distributed/comm/tcp.py", line 264, in write
    async def write(self, msg, serializers=None, on_error="message"):
asyncio.exceptions.CancelledError

During handling of the above exception, another exception occurred:

Traceback (most recent call last):
  File "/easybuild/software/Python/3.10.8-GCCcore-12.2.0/lib/python3.10/asyncio/tasks.py", line 418, in wait_for
    return fut.result()
asyncio.exceptions.CancelledError

The above exception was the direct cause of the following exception:

Traceback (most recent call last):
  File "/home/shankaras1/.venv/lib/python3.10/site-packages/distributed/comm/core.py", line 329, in connect
    await asyncio.wait_for(comm.write(local_info), time_left())
  File "/easybuild/software/Python/3.10.8-GCCcore-12.2.0/lib/python3.10/asyncio/tasks.py", line 420, in wait_for
    raise exceptions.TimeoutError() from exc
asyncio.exceptions.TimeoutError

The above exception was the direct cause of the following exception:

Traceback (most recent call last):
  File "/home/shankaras1/.venv/lib/python3.10/site-packages/distributed/worker.py", line 1161, in heartbeat
    response = await retry_operation(
  File "/home/shankaras1/.venv/lib/python3.10/site-packages/distributed/utils_comm.py", line 383, in retry_operation
    return await retry(
  File "/home/shankaras1/.venv/lib/python3.10/site-packages/distributed/utils_comm.py", line 368, in retry
    return await coro()
  File "/home/shankaras1/.venv/lib/python3.10/site-packages/distributed/core.py", line 1150, in send_recv_from_rpc
    comm = await self.pool.connect(self.addr)
  File "/home/shankaras1/.venv/lib/python3.10/site-packages/distributed/core.py", line 1371, in connect
    return await connect_attempt
  File "/home/shankaras1/.venv/lib/python3.10/site-packages/distributed/core.py", line 1307, in _connect
    comm = await connect(
  File "/home/shankaras1/.venv/lib/python3.10/site-packages/distributed/comm/core.py", line 333, in connect
    raise OSError(
OSError: Timed out during handshake while connecting to tcp://127.0.0.1:39719 after 30 s
2024-05-09 22:08:05,139 - distributed.worker - ERROR - Timed out during handshake while connecting to tcp://127.0.0.1:39719 after 30 s
Traceback (most recent call last):
  File "/home/shankaras1/.venv/lib/python3.10/site-packages/distributed/comm/tcp.py", line 264, in write
    async def write(self, msg, serializers=None, on_error="message"):
asyncio.exceptions.CancelledError

During handling of the above exception, another exception occurred:

Traceback (most recent call last):
  File "/easybuild/software/Python/3.10.8-GCCcore-12.2.0/lib/python3.10/asyncio/tasks.py", line 418, in wait_for
    return fut.result()
asyncio.exceptions.CancelledError

The above exception was the direct cause of the following exception:

Traceback (most recent call last):
  File "/home/shankaras1/.venv/lib/python3.10/site-packages/distributed/comm/core.py", line 329, in connect
    await asyncio.wait_for(comm.write(local_info), time_left())
  File "/easybuild/software/Python/3.10.8-GCCcore-12.2.0/lib/python3.10/asyncio/tasks.py", line 420, in wait_for
    raise exceptions.TimeoutError() from exc
asyncio.exceptions.TimeoutError

The above exception was the direct cause of the following exception:

Traceback (most recent call last):
  File "/home/shankaras1/.venv/lib/python3.10/site-packages/distributed/worker.py", line 1161, in heartbeat
    response = await retry_operation(
  File "/home/shankaras1/.venv/lib/python3.10/site-packages/distributed/utils_comm.py", line 383, in retry_operation
    return await retry(
  File "/home/shankaras1/.venv/lib/python3.10/site-packages/distributed/utils_comm.py", line 368, in retry
    return await coro()
  File "/home/shankaras1/.venv/lib/python3.10/site-packages/distributed/core.py", line 1150, in send_recv_from_rpc
    comm = await self.pool.connect(self.addr)
  File "/home/shankaras1/.venv/lib/python3.10/site-packages/distributed/core.py", line 1371, in connect
    return await connect_attempt
  File "/home/shankaras1/.venv/lib/python3.10/site-packages/distributed/core.py", line 1307, in _connect
    comm = await connect(
  File "/home/shankaras1/.venv/lib/python3.10/site-packages/distributed/comm/core.py", line 333, in connect
    raise OSError(
OSError: Timed out during handshake while connecting to tcp://127.0.0.1:39719 after 30 s
2024-05-09 22:08:04,460 - distributed.worker - ERROR - Timed out during handshake while connecting to tcp://127.0.0.1:39719 after 30 s
Traceback (most recent call last):
  File "/home/shankaras1/.venv/lib/python3.10/site-packages/distributed/comm/tcp.py", line 264, in write
    async def write(self, msg, serializers=None, on_error="message"):
asyncio.exceptions.CancelledError

During handling of the above exception, another exception occurred:

Traceback (most recent call last):
  File "/easybuild/software/Python/3.10.8-GCCcore-12.2.0/lib/python3.10/asyncio/tasks.py", line 418, in wait_for
    return fut.result()
asyncio.exceptions.CancelledError

The above exception was the direct cause of the following exception:

Traceback (most recent call last):
  File "/home/shankaras1/.venv/lib/python3.10/site-packages/distributed/comm/core.py", line 329, in connect
    await asyncio.wait_for(comm.write(local_info), time_left())
  File "/easybuild/software/Python/3.10.8-GCCcore-12.2.0/lib/python3.10/asyncio/tasks.py", line 420, in wait_for
    raise exceptions.TimeoutError() from exc
asyncio.exceptions.TimeoutError

The above exception was the direct cause of the following exception:

Traceback (most recent call last):
  File "/home/shankaras1/.venv/lib/python3.10/site-packages/distributed/worker.py", line 1161, in heartbeat
    response = await retry_operation(
  File "/home/shankaras1/.venv/lib/python3.10/site-packages/distributed/utils_comm.py", line 383, in retry_operation
    return await retry(
  File "/home/shankaras1/.venv/lib/python3.10/site-packages/distributed/utils_comm.py", line 368, in retry
    return await coro()
  File "/home/shankaras1/.venv/lib/python3.10/site-packages/distributed/core.py", line 1150, in send_recv_from_rpc
    comm = await self.pool.connect(self.addr)
  File "/home/shankaras1/.venv/lib/python3.10/site-packages/distributed/core.py", line 1371, in connect
    return await connect_attempt
  File "/home/shankaras1/.venv/lib/python3.10/site-packages/distributed/core.py", line 1307, in _connect
    comm = await connect(
  File "/home/shankaras1/.venv/lib/python3.10/site-packages/distributed/comm/core.py", line 333, in connect
    raise OSError(
OSError: Timed out during handshake while connecting to tcp://127.0.0.1:39719 after 30 s
omega = 0.0100308 finished in 36.62716179899871 seconds.
omega = 0.0100771 entered
2024-05-09 22:08:06,909 - distributed.worker - ERROR - Timed out during handshake while connecting to tcp://127.0.0.1:39719 after 30 s
Traceback (most recent call last):
  File "/home/shankaras1/.venv/lib/python3.10/site-packages/distributed/comm/tcp.py", line 264, in write
    async def write(self, msg, serializers=None, on_error="message"):
asyncio.exceptions.CancelledError

During handling of the above exception, another exception occurred:

Traceback (most recent call last):
  File "/easybuild/software/Python/3.10.8-GCCcore-12.2.0/lib/python3.10/asyncio/tasks.py", line 418, in wait_for
    return fut.result()
asyncio.exceptions.CancelledError

The above exception was the direct cause of the following exception:

Traceback (most recent call last):
  File "/home/shankaras1/.venv/lib/python3.10/site-packages/distributed/comm/core.py", line 329, in connect
    await asyncio.wait_for(comm.write(local_info), time_left())
  File "/easybuild/software/Python/3.10.8-GCCcore-12.2.0/lib/python3.10/asyncio/tasks.py", line 420, in wait_for
    raise exceptions.TimeoutError() from exc
asyncio.exceptions.TimeoutError

The above exception was the direct cause of the following exception:

Traceback (most recent call last):
  File "/home/shankaras1/.venv/lib/python3.10/site-packages/distributed/worker.py", line 1161, in heartbeat
    response = await retry_operation(
  File "/home/shankaras1/.venv/lib/python3.10/site-packages/distributed/utils_comm.py", line 383, in retry_operation
    return await retry(
  File "/home/shankaras1/.venv/lib/python3.10/site-packages/distributed/utils_comm.py", line 368, in retry
    return await coro()
  File "/home/shankaras1/.venv/lib/python3.10/site-packages/distributed/core.py", line 1150, in send_recv_from_rpc
    comm = await self.pool.connect(self.addr)
  File "/home/shankaras1/.venv/lib/python3.10/site-packages/distributed/core.py", line 1371, in connect
    return await connect_attempt
  File "/home/shankaras1/.venv/lib/python3.10/site-packages/distributed/core.py", line 1307, in _connect
    comm = await connect(
  File "/home/shankaras1/.venv/lib/python3.10/site-packages/distributed/comm/core.py", line 333, in connect
    raise OSError(
OSError: Timed out during handshake while connecting to tcp://127.0.0.1:39719 after 30 s
2024-05-09 22:08:04,969 - distributed.worker - ERROR - Timed out during handshake while connecting to tcp://127.0.0.1:39719 after 30 s
Traceback (most recent call last):
  File "/home/shankaras1/.venv/lib/python3.10/site-packages/distributed/comm/tcp.py", line 264, in write
    async def write(self, msg, serializers=None, on_error="message"):
asyncio.exceptions.CancelledError

During handling of the above exception, another exception occurred:

Traceback (most recent call last):
  File "/easybuild/software/Python/3.10.8-GCCcore-12.2.0/lib/python3.10/asyncio/tasks.py", line 418, in wait_for
    return fut.result()
asyncio.exceptions.CancelledError

The above exception was the direct cause of the following exception:

Traceback (most recent call last):
  File "/home/shankaras1/.venv/lib/python3.10/site-packages/distributed/comm/core.py", line 329, in connect
    await asyncio.wait_for(comm.write(local_info), time_left())
  File "/easybuild/software/Python/3.10.8-GCCcore-12.2.0/lib/python3.10/asyncio/tasks.py", line 420, in wait_for
    raise exceptions.TimeoutError() from exc
asyncio.exceptions.TimeoutError

The above exception was the direct cause of the following exception:

Traceback (most recent call last):
  File "/home/shankaras1/.venv/lib/python3.10/site-packages/distributed/worker.py", line 1161, in heartbeat
    response = await retry_operation(
  File "/home/shankaras1/.venv/lib/python3.10/site-packages/distributed/utils_comm.py", line 383, in retry_operation
    return await retry(
  File "/home/shankaras1/.venv/lib/python3.10/site-packages/distributed/utils_comm.py", line 368, in retry
    return await coro()
  File "/home/shankaras1/.venv/lib/python3.10/site-packages/distributed/core.py", line 1150, in send_recv_from_rpc
    comm = await self.pool.connect(self.addr)
  File "/home/shankaras1/.venv/lib/python3.10/site-packages/distributed/core.py", line 1371, in connect
    return await connect_attempt
  File "/home/shankaras1/.venv/lib/python3.10/site-packages/distributed/core.py", line 1307, in _connect
    comm = await connect(
  File "/home/shankaras1/.venv/lib/python3.10/site-packages/distributed/comm/core.py", line 333, in connect
    raise OSError(
OSError: Timed out during handshake while connecting to tcp://127.0.0.1:39719 after 30 s
omega = 0.564829 finished in 37.94724212199799 seconds.
omega = 0.567437 entered
2024-05-09 22:08:08,236 - distributed.worker - ERROR - Timed out during handshake while connecting to tcp://127.0.0.1:39719 after 30 s
Traceback (most recent call last):
  File "/home/shankaras1/.venv/lib/python3.10/site-packages/distributed/comm/tcp.py", line 264, in write
    async def write(self, msg, serializers=None, on_error="message"):
asyncio.exceptions.CancelledError

During handling of the above exception, another exception occurred:

Traceback (most recent call last):
  File "/easybuild/software/Python/3.10.8-GCCcore-12.2.0/lib/python3.10/asyncio/tasks.py", line 418, in wait_for
    return fut.result()
asyncio.exceptions.CancelledError

The above exception was the direct cause of the following exception:

Traceback (most recent call last):
  File "/home/shankaras1/.venv/lib/python3.10/site-packages/distributed/comm/core.py", line 329, in connect
    await asyncio.wait_for(comm.write(local_info), time_left())
  File "/easybuild/software/Python/3.10.8-GCCcore-12.2.0/lib/python3.10/asyncio/tasks.py", line 420, in wait_for
    raise exceptions.TimeoutError() from exc
asyncio.exceptions.TimeoutError

The above exception was the direct cause of the following exception:

Traceback (most recent call last):
  File "/home/shankaras1/.venv/lib/python3.10/site-packages/distributed/worker.py", line 1161, in heartbeat
    response = await retry_operation(
  File "/home/shankaras1/.venv/lib/python3.10/site-packages/distributed/utils_comm.py", line 383, in retry_operation
    return await retry(
  File "/home/shankaras1/.venv/lib/python3.10/site-packages/distributed/utils_comm.py", line 368, in retry
    return await coro()
  File "/home/shankaras1/.venv/lib/python3.10/site-packages/distributed/core.py", line 1150, in send_recv_from_rpc
    comm = await self.pool.connect(self.addr)
  File "/home/shankaras1/.venv/lib/python3.10/site-packages/distributed/core.py", line 1371, in connect
    return await connect_attempt
  File "/home/shankaras1/.venv/lib/python3.10/site-packages/distributed/core.py", line 1307, in _connect
    comm = await connect(
  File "/home/shankaras1/.venv/lib/python3.10/site-packages/distributed/comm/core.py", line 333, in connect
    raise OSError(
OSError: Timed out during handshake while connecting to tcp://127.0.0.1:39719 after 30 s
2024-05-09 22:08:04,651 - distributed.worker - ERROR - Timed out during handshake while connecting to tcp://127.0.0.1:39719 after 30 s
Traceback (most recent call last):
  File "/home/shankaras1/.venv/lib/python3.10/site-packages/distributed/comm/tcp.py", line 264, in write
    async def write(self, msg, serializers=None, on_error="message"):
asyncio.exceptions.CancelledError

During handling of the above exception, another exception occurred:

Traceback (most recent call last):
  File "/easybuild/software/Python/3.10.8-GCCcore-12.2.0/lib/python3.10/asyncio/tasks.py", line 418, in wait_for
    return fut.result()
asyncio.exceptions.CancelledError

The above exception was the direct cause of the following exception:

Traceback (most recent call last):
  File "/home/shankaras1/.venv/lib/python3.10/site-packages/distributed/comm/core.py", line 329, in connect
    await asyncio.wait_for(comm.write(local_info), time_left())
  File "/easybuild/software/Python/3.10.8-GCCcore-12.2.0/lib/python3.10/asyncio/tasks.py", line 420, in wait_for
    raise exceptions.TimeoutError() from exc
asyncio.exceptions.TimeoutError

The above exception was the direct cause of the following exception:

Traceback (most recent call last):
  File "/home/shankaras1/.venv/lib/python3.10/site-packages/distributed/worker.py", line 1161, in heartbeat
    response = await retry_operation(
  File "/home/shankaras1/.venv/lib/python3.10/site-packages/distributed/utils_comm.py", line 383, in retry_operation
    return await retry(
  File "/home/shankaras1/.venv/lib/python3.10/site-packages/distributed/utils_comm.py", line 368, in retry
    return await coro()
  File "/home/shankaras1/.venv/lib/python3.10/site-packages/distributed/core.py", line 1150, in send_recv_from_rpc
    comm = await self.pool.connect(self.addr)
  File "/home/shankaras1/.venv/lib/python3.10/site-packages/distributed/core.py", line 1371, in connect
    return await connect_attempt
  File "/home/shankaras1/.venv/lib/python3.10/site-packages/distributed/core.py", line 1307, in _connect
    comm = await connect(
  File "/home/shankaras1/.venv/lib/python3.10/site-packages/distributed/comm/core.py", line 333, in connect
    raise OSError(
OSError: Timed out during handshake while connecting to tcp://127.0.0.1:39719 after 30 s
omega = 1.77862e-06 finished in 39.05324014299549 seconds.
2024-05-09 22:08:09,322 - distributed.worker - ERROR - Timed out during handshake while connecting to tcp://127.0.0.1:39719 after 30 s
Traceback (most recent call last):
  File "/home/shankaras1/.venv/lib/python3.10/site-packages/distributed/comm/tcp.py", line 264, in write
    async def write(self, msg, serializers=None, on_error="message"):
asyncio.exceptions.CancelledError

During handling of the above exception, another exception occurred:

Traceback (most recent call last):
  File "/easybuild/software/Python/3.10.8-GCCcore-12.2.0/lib/python3.10/asyncio/tasks.py", line 418, in wait_for
    return fut.result()
asyncio.exceptions.CancelledError

The above exception was the direct cause of the following exception:

Traceback (most recent call last):
  File "/home/shankaras1/.venv/lib/python3.10/site-packages/distributed/comm/core.py", line 329, in connect
    await asyncio.wait_for(comm.write(local_info), time_left())
  File "/easybuild/software/Python/3.10.8-GCCcore-12.2.0/lib/python3.10/asyncio/tasks.py", line 420, in wait_for
    raise exceptions.TimeoutError() from exc
asyncio.exceptions.TimeoutError

The above exception was the direct cause of the following exception:

Traceback (most recent call last):
  File "/home/shankaras1/.venv/lib/python3.10/site-packages/distributed/worker.py", line 1161, in heartbeat
    response = await retry_operation(
  File "/home/shankaras1/.venv/lib/python3.10/site-packages/distributed/utils_comm.py", line 383, in retry_operation
    return await retry(
  File "/home/shankaras1/.venv/lib/python3.10/site-packages/distributed/utils_comm.py", line 368, in retry
    return await coro()
  File "/home/shankaras1/.venv/lib/python3.10/site-packages/distributed/core.py", line 1150, in send_recv_from_rpc
    comm = await self.pool.connect(self.addr)
  File "/home/shankaras1/.venv/lib/python3.10/site-packages/distributed/core.py", line 1371, in connect
    return await connect_attempt
  File "/home/shankaras1/.venv/lib/python3.10/site-packages/distributed/core.py", line 1307, in _connect
    comm = await connect(
  File "/home/shankaras1/.venv/lib/python3.10/site-packages/distributed/comm/core.py", line 333, in connect
    raise OSError(
OSError: Timed out during handshake while connecting to tcp://127.0.0.1:39719 after 30 s
2024-05-09 22:08:09,326 - tornado.application - ERROR - Exception in callback functools.partial(<bound method IOLoop._discard_future_result of <tornado.platform.asyncio.AsyncIOLoop object at 0x155548c28b20>>, <Task finished name='Task-16' coro=<Worker.heartbeat() done, defined at /home/shankaras1/.venv/lib/python3.10/site-packages/distributed/worker.py:1153> exception=OSError('Timed out during handshake while connecting to tcp://127.0.0.1:39719 after 30 s')>)
Traceback (most recent call last):
  File "/home/shankaras1/.venv/lib/python3.10/site-packages/distributed/comm/tcp.py", line 264, in write
    async def write(self, msg, serializers=None, on_error="message"):
asyncio.exceptions.CancelledError

During handling of the above exception, another exception occurred:

Traceback (most recent call last):
  File "/easybuild/software/Python/3.10.8-GCCcore-12.2.0/lib/python3.10/asyncio/tasks.py", line 418, in wait_for
    return fut.result()
asyncio.exceptions.CancelledError

The above exception was the direct cause of the following exception:

Traceback (most recent call last):
  File "/home/shankaras1/.venv/lib/python3.10/site-packages/distributed/comm/core.py", line 329, in connect
    await asyncio.wait_for(comm.write(local_info), time_left())
  File "/easybuild/software/Python/3.10.8-GCCcore-12.2.0/lib/python3.10/asyncio/tasks.py", line 420, in wait_for
    raise exceptions.TimeoutError() from exc
asyncio.exceptions.TimeoutError

The above exception was the direct cause of the following exception:

Traceback (most recent call last):
  File "/home/shankaras1/.venv/lib/python3.10/site-packages/tornado/ioloop.py", line 741, in _run_callback
    ret = callback()
  File "/home/shankaras1/.venv/lib/python3.10/site-packages/tornado/ioloop.py", line 765, in _discard_future_result
    future.result()
  File "/home/shankaras1/.venv/lib/python3.10/site-packages/distributed/worker.py", line 1207, in heartbeat
    raise e
  File "/home/shankaras1/.venv/lib/python3.10/site-packages/distributed/worker.py", line 1161, in heartbeat
    response = await retry_operation(
  File "/home/shankaras1/.venv/lib/python3.10/site-packages/distributed/utils_comm.py", line 383, in retry_operation
    return await retry(
  File "/home/shankaras1/.venv/lib/python3.10/site-packages/distributed/utils_comm.py", line 368, in retry
    return await coro()
  File "/home/shankaras1/.venv/lib/python3.10/site-packages/distributed/core.py", line 1150, in send_recv_from_rpc
    comm = await self.pool.connect(self.addr)
  File "/home/shankaras1/.venv/lib/python3.10/site-packages/distributed/core.py", line 1371, in connect
    return await connect_attempt
  File "/home/shankaras1/.venv/lib/python3.10/site-packages/distributed/core.py", line 1307, in _connect
    comm = await connect(
  File "/home/shankaras1/.venv/lib/python3.10/site-packages/distributed/comm/core.py", line 333, in connect
    raise OSError(
OSError: Timed out during handshake while connecting to tcp://127.0.0.1:39719 after 30 s
omega = 1.78683e-06 entered
omega = 5.63097e-05 finished in 39.853311901009874 seconds.
2024-05-09 22:08:10,127 - distributed.worker - ERROR - Timed out during handshake while connecting to tcp://127.0.0.1:39719 after 30 s
Traceback (most recent call last):
  File "/home/shankaras1/.venv/lib/python3.10/site-packages/distributed/comm/tcp.py", line 264, in write
    async def write(self, msg, serializers=None, on_error="message"):
asyncio.exceptions.CancelledError

During handling of the above exception, another exception occurred:

Traceback (most recent call last):
  File "/easybuild/software/Python/3.10.8-GCCcore-12.2.0/lib/python3.10/asyncio/tasks.py", line 418, in wait_for
    return fut.result()
asyncio.exceptions.CancelledError

The above exception was the direct cause of the following exception:

Traceback (most recent call last):
  File "/home/shankaras1/.venv/lib/python3.10/site-packages/distributed/comm/core.py", line 329, in connect
    await asyncio.wait_for(comm.write(local_info), time_left())
  File "/easybuild/software/Python/3.10.8-GCCcore-12.2.0/lib/python3.10/asyncio/tasks.py", line 420, in wait_for
    raise exceptions.TimeoutError() from exc
asyncio.exceptions.TimeoutError

The above exception was the direct cause of the following exception:

Traceback (most recent call last):
  File "/home/shankaras1/.venv/lib/python3.10/site-packages/distributed/worker.py", line 1161, in heartbeat
    response = await retry_operation(
  File "/home/shankaras1/.venv/lib/python3.10/site-packages/distributed/utils_comm.py", line 383, in retry_operation
    return await retry(
  File "/home/shankaras1/.venv/lib/python3.10/site-packages/distributed/utils_comm.py", line 368, in retry
    return await coro()
  File "/home/shankaras1/.venv/lib/python3.10/site-packages/distributed/core.py", line 1150, in send_recv_from_rpc
    comm = await self.pool.connect(self.addr)
  File "/home/shankaras1/.venv/lib/python3.10/site-packages/distributed/core.py", line 1371, in connect
    return await connect_attempt
  File "/home/shankaras1/.venv/lib/python3.10/site-packages/distributed/core.py", line 1307, in _connect
    comm = await connect(
  File "/home/shankaras1/.venv/lib/python3.10/site-packages/distributed/comm/core.py", line 333, in connect
    raise OSError(
OSError: Timed out during handshake while connecting to tcp://127.0.0.1:39719 after 30 s
omega = 5.65697e-05 entered
2024-05-09 22:08:10,130 - tornado.application - ERROR - Exception in callback functools.partial(<bound method IOLoop._discard_future_result of <tornado.platform.asyncio.AsyncIOLoop object at 0x155548c28b50>>, <Task finished name='Task-16' coro=<Worker.heartbeat() done, defined at /home/shankaras1/.venv/lib/python3.10/site-packages/distributed/worker.py:1153> exception=OSError('Timed out during handshake while connecting to tcp://127.0.0.1:39719 after 30 s')>)
Traceback (most recent call last):
  File "/home/shankaras1/.venv/lib/python3.10/site-packages/distributed/comm/tcp.py", line 264, in write
    async def write(self, msg, serializers=None, on_error="message"):
asyncio.exceptions.CancelledError

During handling of the above exception, another exception occurred:

Traceback (most recent call last):
  File "/easybuild/software/Python/3.10.8-GCCcore-12.2.0/lib/python3.10/asyncio/tasks.py", line 418, in wait_for
    return fut.result()
asyncio.exceptions.CancelledError

The above exception was the direct cause of the following exception:

Traceback (most recent call last):
  File "/home/shankaras1/.venv/lib/python3.10/site-packages/distributed/comm/core.py", line 329, in connect
    await asyncio.wait_for(comm.write(local_info), time_left())
  File "/easybuild/software/Python/3.10.8-GCCcore-12.2.0/lib/python3.10/asyncio/tasks.py", line 420, in wait_for
    raise exceptions.TimeoutError() from exc
asyncio.exceptions.TimeoutError

The above exception was the direct cause of the following exception:

Traceback (most recent call last):
  File "/home/shankaras1/.venv/lib/python3.10/site-packages/tornado/ioloop.py", line 741, in _run_callback
    ret = callback()
  File "/home/shankaras1/.venv/lib/python3.10/site-packages/tornado/ioloop.py", line 765, in _discard_future_result
    future.result()
  File "/home/shankaras1/.venv/lib/python3.10/site-packages/distributed/worker.py", line 1207, in heartbeat
    raise e
  File "/home/shankaras1/.venv/lib/python3.10/site-packages/distributed/worker.py", line 1161, in heartbeat
    response = await retry_operation(
  File "/home/shankaras1/.venv/lib/python3.10/site-packages/distributed/utils_comm.py", line 383, in retry_operation
    return await retry(
  File "/home/shankaras1/.venv/lib/python3.10/site-packages/distributed/utils_comm.py", line 368, in retry
    return await coro()
  File "/home/shankaras1/.venv/lib/python3.10/site-packages/distributed/core.py", line 1150, in send_recv_from_rpc
    comm = await self.pool.connect(self.addr)
  File "/home/shankaras1/.venv/lib/python3.10/site-packages/distributed/core.py", line 1371, in connect
    return await connect_attempt
  File "/home/shankaras1/.venv/lib/python3.10/site-packages/distributed/core.py", line 1307, in _connect
    comm = await connect(
  File "/home/shankaras1/.venv/lib/python3.10/site-packages/distributed/comm/core.py", line 333, in connect
    raise OSError(
OSError: Timed out during handshake while connecting to tcp://127.0.0.1:39719 after 30 s
omega = 3.16349e-06 finished in 39.88670775500941 seconds.
2024-05-09 22:08:10,155 - distributed.worker - ERROR - Timed out during handshake while connecting to tcp://127.0.0.1:39719 after 30 s
Traceback (most recent call last):
  File "/home/shankaras1/.venv/lib/python3.10/site-packages/distributed/comm/tcp.py", line 264, in write
    async def write(self, msg, serializers=None, on_error="message"):
asyncio.exceptions.CancelledError

During handling of the above exception, another exception occurred:

Traceback (most recent call last):
  File "/easybuild/software/Python/3.10.8-GCCcore-12.2.0/lib/python3.10/asyncio/tasks.py", line 418, in wait_for
    return fut.result()
asyncio.exceptions.CancelledError

The above exception was the direct cause of the following exception:

Traceback (most recent call last):
  File "/home/shankaras1/.venv/lib/python3.10/site-packages/distributed/comm/core.py", line 329, in connect
    await asyncio.wait_for(comm.write(local_info), time_left())
  File "/easybuild/software/Python/3.10.8-GCCcore-12.2.0/lib/python3.10/asyncio/tasks.py", line 420, in wait_for
    raise exceptions.TimeoutError() from exc
asyncio.exceptions.TimeoutError

The above exception was the direct cause of the following exception:

Traceback (most recent call last):
  File "/home/shankaras1/.venv/lib/python3.10/site-packages/distributed/worker.py", line 1161, in heartbeat
    response = await retry_operation(
  File "/home/shankaras1/.venv/lib/python3.10/site-packages/distributed/utils_comm.py", line 383, in retry_operation
    return await retry(
  File "/home/shankaras1/.venv/lib/python3.10/site-packages/distributed/utils_comm.py", line 368, in retry
    return await coro()
  File "/home/shankaras1/.venv/lib/python3.10/site-packages/distributed/core.py", line 1150, in send_recv_from_rpc
    comm = await self.pool.connect(self.addr)
  File "/home/shankaras1/.venv/lib/python3.10/site-packages/distributed/core.py", line 1371, in connect
    return await connect_attempt
  File "/home/shankaras1/.venv/lib/python3.10/site-packages/distributed/core.py", line 1307, in _connect
    comm = await connect(
  File "/home/shankaras1/.venv/lib/python3.10/site-packages/distributed/comm/core.py", line 333, in connect
    raise OSError(
OSError: Timed out during handshake while connecting to tcp://127.0.0.1:39719 after 30 s
omega = 3.1781e-06 entered
2024-05-09 22:08:10,158 - tornado.application - ERROR - Exception in callback functools.partial(<bound method IOLoop._discard_future_result of <tornado.platform.asyncio.AsyncIOLoop object at 0x155548c28b20>>, <Task finished name='Task-16' coro=<Worker.heartbeat() done, defined at /home/shankaras1/.venv/lib/python3.10/site-packages/distributed/worker.py:1153> exception=OSError('Timed out during handshake while connecting to tcp://127.0.0.1:39719 after 30 s')>)
Traceback (most recent call last):
  File "/home/shankaras1/.venv/lib/python3.10/site-packages/distributed/comm/tcp.py", line 264, in write
    async def write(self, msg, serializers=None, on_error="message"):
asyncio.exceptions.CancelledError

During handling of the above exception, another exception occurred:

Traceback (most recent call last):
  File "/easybuild/software/Python/3.10.8-GCCcore-12.2.0/lib/python3.10/asyncio/tasks.py", line 418, in wait_for
    return fut.result()
asyncio.exceptions.CancelledError

The above exception was the direct cause of the following exception:

Traceback (most recent call last):
  File "/home/shankaras1/.venv/lib/python3.10/site-packages/distributed/comm/core.py", line 329, in connect
    await asyncio.wait_for(comm.write(local_info), time_left())
  File "/easybuild/software/Python/3.10.8-GCCcore-12.2.0/lib/python3.10/asyncio/tasks.py", line 420, in wait_for
    raise exceptions.TimeoutError() from exc
asyncio.exceptions.TimeoutError

The above exception was the direct cause of the following exception:

Traceback (most recent call last):
  File "/home/shankaras1/.venv/lib/python3.10/site-packages/tornado/ioloop.py", line 741, in _run_callback
    ret = callback()
  File "/home/shankaras1/.venv/lib/python3.10/site-packages/tornado/ioloop.py", line 765, in _discard_future_result
    future.result()
  File "/home/shankaras1/.venv/lib/python3.10/site-packages/distributed/worker.py", line 1207, in heartbeat
    raise e
  File "/home/shankaras1/.venv/lib/python3.10/site-packages/distributed/worker.py", line 1161, in heartbeat
    response = await retry_operation(
  File "/home/shankaras1/.venv/lib/python3.10/site-packages/distributed/utils_comm.py", line 383, in retry_operation
    return await retry(
  File "/home/shankaras1/.venv/lib/python3.10/site-packages/distributed/utils_comm.py", line 368, in retry
    return await coro()
  File "/home/shankaras1/.venv/lib/python3.10/site-packages/distributed/core.py", line 1150, in send_recv_from_rpc
    comm = await self.pool.connect(self.addr)
  File "/home/shankaras1/.venv/lib/python3.10/site-packages/distributed/core.py", line 1371, in connect
    return await connect_attempt
  File "/home/shankaras1/.venv/lib/python3.10/site-packages/distributed/core.py", line 1307, in _connect
    comm = await connect(
  File "/home/shankaras1/.venv/lib/python3.10/site-packages/distributed/comm/core.py", line 333, in connect
    raise OSError(
OSError: Timed out during handshake while connecting to tcp://127.0.0.1:39719 after 30 s
2024-05-09 22:08:04,586 - distributed.worker - ERROR - Timed out during handshake while connecting to tcp://127.0.0.1:39719 after 30 s
Traceback (most recent call last):
  File "/home/shankaras1/.venv/lib/python3.10/site-packages/distributed/comm/tcp.py", line 264, in write
    async def write(self, msg, serializers=None, on_error="message"):
asyncio.exceptions.CancelledError

During handling of the above exception, another exception occurred:

Traceback (most recent call last):
  File "/easybuild/software/Python/3.10.8-GCCcore-12.2.0/lib/python3.10/asyncio/tasks.py", line 418, in wait_for
    return fut.result()
asyncio.exceptions.CancelledError

The above exception was the direct cause of the following exception:

Traceback (most recent call last):
  File "/home/shankaras1/.venv/lib/python3.10/site-packages/distributed/comm/core.py", line 329, in connect
    await asyncio.wait_for(comm.write(local_info), time_left())
  File "/easybuild/software/Python/3.10.8-GCCcore-12.2.0/lib/python3.10/asyncio/tasks.py", line 420, in wait_for
    raise exceptions.TimeoutError() from exc
asyncio.exceptions.TimeoutError

The above exception was the direct cause of the following exception:

Traceback (most recent call last):
  File "/home/shankaras1/.venv/lib/python3.10/site-packages/distributed/worker.py", line 1161, in heartbeat
    response = await retry_operation(
  File "/home/shankaras1/.venv/lib/python3.10/site-packages/distributed/utils_comm.py", line 383, in retry_operation
    return await retry(
  File "/home/shankaras1/.venv/lib/python3.10/site-packages/distributed/utils_comm.py", line 368, in retry
    return await coro()
  File "/home/shankaras1/.venv/lib/python3.10/site-packages/distributed/core.py", line 1150, in send_recv_from_rpc
    comm = await self.pool.connect(self.addr)
  File "/home/shankaras1/.venv/lib/python3.10/site-packages/distributed/core.py", line 1371, in connect
    return await connect_attempt
  File "/home/shankaras1/.venv/lib/python3.10/site-packages/distributed/core.py", line 1307, in _connect
    comm = await connect(
  File "/home/shankaras1/.venv/lib/python3.10/site-packages/distributed/comm/core.py", line 333, in connect
    raise OSError(
OSError: Timed out during handshake while connecting to tcp://127.0.0.1:39719 after 30 s
2024-05-09 22:08:04,496 - distributed.worker - ERROR - Timed out during handshake while connecting to tcp://127.0.0.1:39719 after 30 s
Traceback (most recent call last):
  File "/home/shankaras1/.venv/lib/python3.10/site-packages/distributed/comm/tcp.py", line 264, in write
    async def write(self, msg, serializers=None, on_error="message"):
asyncio.exceptions.CancelledError

During handling of the above exception, another exception occurred:

Traceback (most recent call last):
  File "/easybuild/software/Python/3.10.8-GCCcore-12.2.0/lib/python3.10/asyncio/tasks.py", line 418, in wait_for
    return fut.result()
asyncio.exceptions.CancelledError

The above exception was the direct cause of the following exception:

Traceback (most recent call last):
  File "/home/shankaras1/.venv/lib/python3.10/site-packages/distributed/comm/core.py", line 329, in connect
    await asyncio.wait_for(comm.write(local_info), time_left())
  File "/easybuild/software/Python/3.10.8-GCCcore-12.2.0/lib/python3.10/asyncio/tasks.py", line 420, in wait_for
    raise exceptions.TimeoutError() from exc
asyncio.exceptions.TimeoutError

The above exception was the direct cause of the following exception:

Traceback (most recent call last):
  File "/home/shankaras1/.venv/lib/python3.10/site-packages/distributed/worker.py", line 1161, in heartbeat
    response = await retry_operation(
  File "/home/shankaras1/.venv/lib/python3.10/site-packages/distributed/utils_comm.py", line 383, in retry_operation
    return await retry(
  File "/home/shankaras1/.venv/lib/python3.10/site-packages/distributed/utils_comm.py", line 368, in retry
    return await coro()
  File "/home/shankaras1/.venv/lib/python3.10/site-packages/distributed/core.py", line 1150, in send_recv_from_rpc
    comm = await self.pool.connect(self.addr)
  File "/home/shankaras1/.venv/lib/python3.10/site-packages/distributed/core.py", line 1371, in connect
    return await connect_attempt
  File "/home/shankaras1/.venv/lib/python3.10/site-packages/distributed/core.py", line 1307, in _connect
    comm = await connect(
  File "/home/shankaras1/.venv/lib/python3.10/site-packages/distributed/comm/core.py", line 333, in connect
    raise OSError(
OSError: Timed out during handshake while connecting to tcp://127.0.0.1:39719 after 30 s
omega = 5.62665e-06 finished in 40.43314540700521 seconds.
omega = 5.65263e-06 entered
omega = 1e-06 finished in 40.468933319003554 seconds.
omega = 1.00462e-06 entered
omega = 1.00077e-05 finished in 40.82886006098124 seconds.
2024-05-09 22:08:11,100 - distributed.worker - ERROR - Timed out during handshake while connecting to tcp://127.0.0.1:39719 after 30 s
Traceback (most recent call last):
  File "/home/shankaras1/.venv/lib/python3.10/site-packages/distributed/comm/tcp.py", line 264, in write
    async def write(self, msg, serializers=None, on_error="message"):
asyncio.exceptions.CancelledError

During handling of the above exception, another exception occurred:

Traceback (most recent call last):
  File "/easybuild/software/Python/3.10.8-GCCcore-12.2.0/lib/python3.10/asyncio/tasks.py", line 418, in wait_for
    return fut.result()
asyncio.exceptions.CancelledError

The above exception was the direct cause of the following exception:

Traceback (most recent call last):
  File "/home/shankaras1/.venv/lib/python3.10/site-packages/distributed/comm/core.py", line 329, in connect
    await asyncio.wait_for(comm.write(local_info), time_left())
  File "/easybuild/software/Python/3.10.8-GCCcore-12.2.0/lib/python3.10/asyncio/tasks.py", line 420, in wait_for
    raise exceptions.TimeoutError() from exc
asyncio.exceptions.TimeoutError

The above exception was the direct cause of the following exception:

Traceback (most recent call last):
  File "/home/shankaras1/.venv/lib/python3.10/site-packages/distributed/worker.py", line 1161, in heartbeat
    response = await retry_operation(
  File "/home/shankaras1/.venv/lib/python3.10/site-packages/distributed/utils_comm.py", line 383, in retry_operation
    return await retry(
  File "/home/shankaras1/.venv/lib/python3.10/site-packages/distributed/utils_comm.py", line 368, in retry
    return await coro()
  File "/home/shankaras1/.venv/lib/python3.10/site-packages/distributed/core.py", line 1150, in send_recv_from_rpc
    comm = await self.pool.connect(self.addr)
  File "/home/shankaras1/.venv/lib/python3.10/site-packages/distributed/core.py", line 1371, in connect
    return await connect_attempt
  File "/home/shankaras1/.venv/lib/python3.10/site-packages/distributed/core.py", line 1307, in _connect
    comm = await connect(
  File "/home/shankaras1/.venv/lib/python3.10/site-packages/distributed/comm/core.py", line 333, in connect
    raise OSError(
OSError: Timed out during handshake while connecting to tcp://127.0.0.1:39719 after 30 s
omega = 1.00539e-05 entered
2024-05-09 22:08:11,103 - tornado.application - ERROR - Exception in callback functools.partial(<bound method IOLoop._discard_future_result of <tornado.platform.asyncio.AsyncIOLoop object at 0x155548c28b20>>, <Task finished name='Task-16' coro=<Worker.heartbeat() done, defined at /home/shankaras1/.venv/lib/python3.10/site-packages/distributed/worker.py:1153> exception=OSError('Timed out during handshake while connecting to tcp://127.0.0.1:39719 after 30 s')>)
Traceback (most recent call last):
  File "/home/shankaras1/.venv/lib/python3.10/site-packages/distributed/comm/tcp.py", line 264, in write
    async def write(self, msg, serializers=None, on_error="message"):
asyncio.exceptions.CancelledError

During handling of the above exception, another exception occurred:

Traceback (most recent call last):
  File "/easybuild/software/Python/3.10.8-GCCcore-12.2.0/lib/python3.10/asyncio/tasks.py", line 418, in wait_for
    return fut.result()
asyncio.exceptions.CancelledError

The above exception was the direct cause of the following exception:

Traceback (most recent call last):
  File "/home/shankaras1/.venv/lib/python3.10/site-packages/distributed/comm/core.py", line 329, in connect
    await asyncio.wait_for(comm.write(local_info), time_left())
  File "/easybuild/software/Python/3.10.8-GCCcore-12.2.0/lib/python3.10/asyncio/tasks.py", line 420, in wait_for
    raise exceptions.TimeoutError() from exc
asyncio.exceptions.TimeoutError

The above exception was the direct cause of the following exception:

Traceback (most recent call last):
  File "/home/shankaras1/.venv/lib/python3.10/site-packages/tornado/ioloop.py", line 741, in _run_callback
    ret = callback()
  File "/home/shankaras1/.venv/lib/python3.10/site-packages/tornado/ioloop.py", line 765, in _discard_future_result
    future.result()
  File "/home/shankaras1/.venv/lib/python3.10/site-packages/distributed/worker.py", line 1207, in heartbeat
    raise e
  File "/home/shankaras1/.venv/lib/python3.10/site-packages/distributed/worker.py", line 1161, in heartbeat
    response = await retry_operation(
  File "/home/shankaras1/.venv/lib/python3.10/site-packages/distributed/utils_comm.py", line 383, in retry_operation
    return await retry(
  File "/home/shankaras1/.venv/lib/python3.10/site-packages/distributed/utils_comm.py", line 368, in retry
    return await coro()
  File "/home/shankaras1/.venv/lib/python3.10/site-packages/distributed/core.py", line 1150, in send_recv_from_rpc
    comm = await self.pool.connect(self.addr)
  File "/home/shankaras1/.venv/lib/python3.10/site-packages/distributed/core.py", line 1371, in connect
    return await connect_attempt
  File "/home/shankaras1/.venv/lib/python3.10/site-packages/distributed/core.py", line 1307, in _connect
    comm = await connect(
  File "/home/shankaras1/.venv/lib/python3.10/site-packages/distributed/comm/core.py", line 333, in connect
    raise OSError(
OSError: Timed out during handshake while connecting to tcp://127.0.0.1:39719 after 30 s
omega = 0.000100154 finished in 40.99891191200004 seconds.
omega = 0.000100616 entered
2024-05-09 22:08:08,996 - tornado.application - ERROR - Exception in callback functools.partial(<bound method IOLoop._discard_future_result of <tornado.platform.asyncio.AsyncIOLoop object at 0x155548c28b20>>, <Task finished name='Task-16' coro=<Worker.heartbeat() done, defined at /home/shankaras1/.venv/lib/python3.10/site-packages/distributed/worker.py:1153> exception=OSError('Timed out during handshake while connecting to tcp://127.0.0.1:39719 after 30 s')>)
Traceback (most recent call last):
  File "/home/shankaras1/.venv/lib/python3.10/site-packages/distributed/comm/tcp.py", line 264, in write
    async def write(self, msg, serializers=None, on_error="message"):
asyncio.exceptions.CancelledError

During handling of the above exception, another exception occurred:

Traceback (most recent call last):
  File "/easybuild/software/Python/3.10.8-GCCcore-12.2.0/lib/python3.10/asyncio/tasks.py", line 418, in wait_for
    return fut.result()
asyncio.exceptions.CancelledError

The above exception was the direct cause of the following exception:

Traceback (most recent call last):
  File "/home/shankaras1/.venv/lib/python3.10/site-packages/distributed/comm/core.py", line 329, in connect
    await asyncio.wait_for(comm.write(local_info), time_left())
  File "/easybuild/software/Python/3.10.8-GCCcore-12.2.0/lib/python3.10/asyncio/tasks.py", line 420, in wait_for
    raise exceptions.TimeoutError() from exc
asyncio.exceptions.TimeoutError

The above exception was the direct cause of the following exception:

Traceback (most recent call last):
  File "/home/shankaras1/.venv/lib/python3.10/site-packages/tornado/ioloop.py", line 741, in _run_callback
    ret = callback()
  File "/home/shankaras1/.venv/lib/python3.10/site-packages/tornado/ioloop.py", line 765, in _discard_future_result
    future.result()
  File "/home/shankaras1/.venv/lib/python3.10/site-packages/distributed/worker.py", line 1207, in heartbeat
    raise e
  File "/home/shankaras1/.venv/lib/python3.10/site-packages/distributed/worker.py", line 1161, in heartbeat
    response = await retry_operation(
  File "/home/shankaras1/.venv/lib/python3.10/site-packages/distributed/utils_comm.py", line 383, in retry_operation
    return await retry(
  File "/home/shankaras1/.venv/lib/python3.10/site-packages/distributed/utils_comm.py", line 368, in retry
    return await coro()
  File "/home/shankaras1/.venv/lib/python3.10/site-packages/distributed/core.py", line 1150, in send_recv_from_rpc
    comm = await self.pool.connect(self.addr)
  File "/home/shankaras1/.venv/lib/python3.10/site-packages/distributed/core.py", line 1371, in connect
    return await connect_attempt
  File "/home/shankaras1/.venv/lib/python3.10/site-packages/distributed/core.py", line 1307, in _connect
    comm = await connect(
  File "/home/shankaras1/.venv/lib/python3.10/site-packages/distributed/comm/core.py", line 333, in connect
    raise OSError(
OSError: Timed out during handshake while connecting to tcp://127.0.0.1:39719 after 30 s
omega = 1.77999e-05 finished in 41.2984921640018 seconds.
omega = 1.78821e-05 entered
2024-05-09 22:08:06,825 - tornado.application - ERROR - Exception in callback functools.partial(<bound method IOLoop._discard_future_result of <tornado.platform.asyncio.AsyncIOLoop object at 0x155548c28b20>>, <Task finished name='Task-16' coro=<Worker.heartbeat() done, defined at /home/shankaras1/.venv/lib/python3.10/site-packages/distributed/worker.py:1153> exception=OSError('Timed out during handshake while connecting to tcp://127.0.0.1:39719 after 30 s')>)
Traceback (most recent call last):
  File "/home/shankaras1/.venv/lib/python3.10/site-packages/distributed/comm/tcp.py", line 264, in write
    async def write(self, msg, serializers=None, on_error="message"):
asyncio.exceptions.CancelledError

During handling of the above exception, another exception occurred:

Traceback (most recent call last):
  File "/easybuild/software/Python/3.10.8-GCCcore-12.2.0/lib/python3.10/asyncio/tasks.py", line 418, in wait_for
    return fut.result()
asyncio.exceptions.CancelledError

The above exception was the direct cause of the following exception:

Traceback (most recent call last):
  File "/home/shankaras1/.venv/lib/python3.10/site-packages/distributed/comm/core.py", line 329, in connect
    await asyncio.wait_for(comm.write(local_info), time_left())
  File "/easybuild/software/Python/3.10.8-GCCcore-12.2.0/lib/python3.10/asyncio/tasks.py", line 420, in wait_for
    raise exceptions.TimeoutError() from exc
asyncio.exceptions.TimeoutError

The above exception was the direct cause of the following exception:

Traceback (most recent call last):
  File "/home/shankaras1/.venv/lib/python3.10/site-packages/tornado/ioloop.py", line 741, in _run_callback
    ret = callback()
  File "/home/shankaras1/.venv/lib/python3.10/site-packages/tornado/ioloop.py", line 765, in _discard_future_result
    future.result()
  File "/home/shankaras1/.venv/lib/python3.10/site-packages/distributed/worker.py", line 1207, in heartbeat
    raise e
  File "/home/shankaras1/.venv/lib/python3.10/site-packages/distributed/worker.py", line 1161, in heartbeat
    response = await retry_operation(
  File "/home/shankaras1/.venv/lib/python3.10/site-packages/distributed/utils_comm.py", line 383, in retry_operation
    return await retry(
  File "/home/shankaras1/.venv/lib/python3.10/site-packages/distributed/utils_comm.py", line 368, in retry
    return await coro()
  File "/home/shankaras1/.venv/lib/python3.10/site-packages/distributed/core.py", line 1150, in send_recv_from_rpc
    comm = await self.pool.connect(self.addr)
  File "/home/shankaras1/.venv/lib/python3.10/site-packages/distributed/core.py", line 1371, in connect
    return await connect_attempt
  File "/home/shankaras1/.venv/lib/python3.10/site-packages/distributed/core.py", line 1307, in _connect
    comm = await connect(
  File "/home/shankaras1/.venv/lib/python3.10/site-packages/distributed/comm/core.py", line 333, in connect
    raise OSError(
OSError: Timed out during handshake while connecting to tcp://127.0.0.1:39719 after 30 s
2024-05-09 22:08:06,123 - tornado.application - ERROR - Exception in callback functools.partial(<bound method IOLoop._discard_future_result of <tornado.platform.asyncio.AsyncIOLoop object at 0x155548c28b20>>, <Task finished name='Task-16' coro=<Worker.heartbeat() done, defined at /home/shankaras1/.venv/lib/python3.10/site-packages/distributed/worker.py:1153> exception=OSError('Timed out during handshake while connecting to tcp://127.0.0.1:39719 after 30 s')>)
Traceback (most recent call last):
  File "/home/shankaras1/.venv/lib/python3.10/site-packages/distributed/comm/tcp.py", line 264, in write
    async def write(self, msg, serializers=None, on_error="message"):
asyncio.exceptions.CancelledError

During handling of the above exception, another exception occurred:

Traceback (most recent call last):
  File "/easybuild/software/Python/3.10.8-GCCcore-12.2.0/lib/python3.10/asyncio/tasks.py", line 418, in wait_for
    return fut.result()
asyncio.exceptions.CancelledError

The above exception was the direct cause of the following exception:

Traceback (most recent call last):
  File "/home/shankaras1/.venv/lib/python3.10/site-packages/distributed/comm/core.py", line 329, in connect
    await asyncio.wait_for(comm.write(local_info), time_left())
  File "/easybuild/software/Python/3.10.8-GCCcore-12.2.0/lib/python3.10/asyncio/tasks.py", line 420, in wait_for
    raise exceptions.TimeoutError() from exc
asyncio.exceptions.TimeoutError

The above exception was the direct cause of the following exception:

Traceback (most recent call last):
  File "/home/shankaras1/.venv/lib/python3.10/site-packages/tornado/ioloop.py", line 741, in _run_callback
    ret = callback()
  File "/home/shankaras1/.venv/lib/python3.10/site-packages/tornado/ioloop.py", line 765, in _discard_future_result
    future.result()
  File "/home/shankaras1/.venv/lib/python3.10/site-packages/distributed/worker.py", line 1207, in heartbeat
    raise e
  File "/home/shankaras1/.venv/lib/python3.10/site-packages/distributed/worker.py", line 1161, in heartbeat
    response = await retry_operation(
  File "/home/shankaras1/.venv/lib/python3.10/site-packages/distributed/utils_comm.py", line 383, in retry_operation
    return await retry(
  File "/home/shankaras1/.venv/lib/python3.10/site-packages/distributed/utils_comm.py", line 368, in retry
    return await coro()
  File "/home/shankaras1/.venv/lib/python3.10/site-packages/distributed/core.py", line 1150, in send_recv_from_rpc
    comm = await self.pool.connect(self.addr)
  File "/home/shankaras1/.venv/lib/python3.10/site-packages/distributed/core.py", line 1371, in connect
    return await connect_attempt
  File "/home/shankaras1/.venv/lib/python3.10/site-packages/distributed/core.py", line 1307, in _connect
    comm = await connect(
  File "/home/shankaras1/.venv/lib/python3.10/site-packages/distributed/comm/core.py", line 333, in connect
    raise OSError(
OSError: Timed out during handshake while connecting to tcp://127.0.0.1:39719 after 30 s
omega = 0.000178135 finished in 42.347788970015245 seconds.
2024-05-09 22:08:12,624 - distributed.worker - ERROR - Timed out during handshake while connecting to tcp://127.0.0.1:39719 after 30 s
Traceback (most recent call last):
  File "/home/shankaras1/.venv/lib/python3.10/site-packages/distributed/comm/tcp.py", line 264, in write
    async def write(self, msg, serializers=None, on_error="message"):
asyncio.exceptions.CancelledError

During handling of the above exception, another exception occurred:

Traceback (most recent call last):
  File "/easybuild/software/Python/3.10.8-GCCcore-12.2.0/lib/python3.10/asyncio/tasks.py", line 418, in wait_for
    return fut.result()
asyncio.exceptions.CancelledError

The above exception was the direct cause of the following exception:

Traceback (most recent call last):
  File "/home/shankaras1/.venv/lib/python3.10/site-packages/distributed/comm/core.py", line 329, in connect
    await asyncio.wait_for(comm.write(local_info), time_left())
  File "/easybuild/software/Python/3.10.8-GCCcore-12.2.0/lib/python3.10/asyncio/tasks.py", line 420, in wait_for
    raise exceptions.TimeoutError() from exc
asyncio.exceptions.TimeoutError

The above exception was the direct cause of the following exception:

Traceback (most recent call last):
  File "/home/shankaras1/.venv/lib/python3.10/site-packages/distributed/worker.py", line 1161, in heartbeat
    response = await retry_operation(
  File "/home/shankaras1/.venv/lib/python3.10/site-packages/distributed/utils_comm.py", line 383, in retry_operation
    return await retry(
  File "/home/shankaras1/.venv/lib/python3.10/site-packages/distributed/utils_comm.py", line 368, in retry
    return await coro()
  File "/home/shankaras1/.venv/lib/python3.10/site-packages/distributed/core.py", line 1150, in send_recv_from_rpc
    comm = await self.pool.connect(self.addr)
  File "/home/shankaras1/.venv/lib/python3.10/site-packages/distributed/core.py", line 1371, in connect
    return await connect_attempt
  File "/home/shankaras1/.venv/lib/python3.10/site-packages/distributed/core.py", line 1307, in _connect
    comm = await connect(
  File "/home/shankaras1/.venv/lib/python3.10/site-packages/distributed/comm/core.py", line 333, in connect
    raise OSError(
OSError: Timed out during handshake while connecting to tcp://127.0.0.1:39719 after 30 s
omega = 0.000178958 entered
2024-05-09 22:08:12,627 - tornado.application - ERROR - Exception in callback functools.partial(<bound method IOLoop._discard_future_result of <tornado.platform.asyncio.AsyncIOLoop object at 0x155548c28b20>>, <Task finished name='Task-16' coro=<Worker.heartbeat() done, defined at /home/shankaras1/.venv/lib/python3.10/site-packages/distributed/worker.py:1153> exception=OSError('Timed out during handshake while connecting to tcp://127.0.0.1:39719 after 30 s')>)
Traceback (most recent call last):
  File "/home/shankaras1/.venv/lib/python3.10/site-packages/distributed/comm/tcp.py", line 264, in write
    async def write(self, msg, serializers=None, on_error="message"):
asyncio.exceptions.CancelledError

During handling of the above exception, another exception occurred:

Traceback (most recent call last):
  File "/easybuild/software/Python/3.10.8-GCCcore-12.2.0/lib/python3.10/asyncio/tasks.py", line 418, in wait_for
    return fut.result()
asyncio.exceptions.CancelledError

The above exception was the direct cause of the following exception:

Traceback (most recent call last):
  File "/home/shankaras1/.venv/lib/python3.10/site-packages/distributed/comm/core.py", line 329, in connect
    await asyncio.wait_for(comm.write(local_info), time_left())
  File "/easybuild/software/Python/3.10.8-GCCcore-12.2.0/lib/python3.10/asyncio/tasks.py", line 420, in wait_for
    raise exceptions.TimeoutError() from exc
asyncio.exceptions.TimeoutError

The above exception was the direct cause of the following exception:

Traceback (most recent call last):
  File "/home/shankaras1/.venv/lib/python3.10/site-packages/tornado/ioloop.py", line 741, in _run_callback
    ret = callback()
  File "/home/shankaras1/.venv/lib/python3.10/site-packages/tornado/ioloop.py", line 765, in _discard_future_result
    future.result()
  File "/home/shankaras1/.venv/lib/python3.10/site-packages/distributed/worker.py", line 1207, in heartbeat
    raise e
  File "/home/shankaras1/.venv/lib/python3.10/site-packages/distributed/worker.py", line 1161, in heartbeat
    response = await retry_operation(
  File "/home/shankaras1/.venv/lib/python3.10/site-packages/distributed/utils_comm.py", line 383, in retry_operation
    return await retry(
  File "/home/shankaras1/.venv/lib/python3.10/site-packages/distributed/utils_comm.py", line 368, in retry
    return await coro()
  File "/home/shankaras1/.venv/lib/python3.10/site-packages/distributed/core.py", line 1150, in send_recv_from_rpc
    comm = await self.pool.connect(self.addr)
  File "/home/shankaras1/.venv/lib/python3.10/site-packages/distributed/core.py", line 1371, in connect
    return await connect_attempt
  File "/home/shankaras1/.venv/lib/python3.10/site-packages/distributed/core.py", line 1307, in _connect
    comm = await connect(
  File "/home/shankaras1/.venv/lib/python3.10/site-packages/distributed/comm/core.py", line 333, in connect
    raise OSError(
OSError: Timed out during handshake while connecting to tcp://127.0.0.1:39719 after 30 s
omega = 3.16592e-05 finished in 42.52351896298933 seconds.
omega = 3.18054e-05 entered
2024-05-09 22:08:12,798 - distributed.worker - ERROR - Timed out during handshake while connecting to tcp://127.0.0.1:39719 after 30 s
Traceback (most recent call last):
  File "/home/shankaras1/.venv/lib/python3.10/site-packages/distributed/comm/tcp.py", line 264, in write
    async def write(self, msg, serializers=None, on_error="message"):
asyncio.exceptions.CancelledError

During handling of the above exception, another exception occurred:

Traceback (most recent call last):
  File "/easybuild/software/Python/3.10.8-GCCcore-12.2.0/lib/python3.10/asyncio/tasks.py", line 418, in wait_for
    return fut.result()
asyncio.exceptions.CancelledError

The above exception was the direct cause of the following exception:

Traceback (most recent call last):
  File "/home/shankaras1/.venv/lib/python3.10/site-packages/distributed/comm/core.py", line 329, in connect
    await asyncio.wait_for(comm.write(local_info), time_left())
  File "/easybuild/software/Python/3.10.8-GCCcore-12.2.0/lib/python3.10/asyncio/tasks.py", line 420, in wait_for
    raise exceptions.TimeoutError() from exc
asyncio.exceptions.TimeoutError

The above exception was the direct cause of the following exception:

Traceback (most recent call last):
  File "/home/shankaras1/.venv/lib/python3.10/site-packages/distributed/worker.py", line 1161, in heartbeat
    response = await retry_operation(
  File "/home/shankaras1/.venv/lib/python3.10/site-packages/distributed/utils_comm.py", line 383, in retry_operation
    return await retry(
  File "/home/shankaras1/.venv/lib/python3.10/site-packages/distributed/utils_comm.py", line 368, in retry
    return await coro()
  File "/home/shankaras1/.venv/lib/python3.10/site-packages/distributed/core.py", line 1150, in send_recv_from_rpc
    comm = await self.pool.connect(self.addr)
  File "/home/shankaras1/.venv/lib/python3.10/site-packages/distributed/core.py", line 1371, in connect
    return await connect_attempt
  File "/home/shankaras1/.venv/lib/python3.10/site-packages/distributed/core.py", line 1307, in _connect
    comm = await connect(
  File "/home/shankaras1/.venv/lib/python3.10/site-packages/distributed/comm/core.py", line 333, in connect
    raise OSError(
OSError: Timed out during handshake while connecting to tcp://127.0.0.1:39719 after 30 s
2024-05-09 22:08:08,168 - tornado.application - ERROR - Exception in callback functools.partial(<bound method IOLoop._discard_future_result of <tornado.platform.asyncio.AsyncIOLoop object at 0x155548c28b20>>, <Task finished name='Task-16' coro=<Worker.heartbeat() done, defined at /home/shankaras1/.venv/lib/python3.10/site-packages/distributed/worker.py:1153> exception=OSError('Timed out during handshake while connecting to tcp://127.0.0.1:39719 after 30 s')>)
Traceback (most recent call last):
  File "/home/shankaras1/.venv/lib/python3.10/site-packages/distributed/comm/tcp.py", line 264, in write
    async def write(self, msg, serializers=None, on_error="message"):
asyncio.exceptions.CancelledError

During handling of the above exception, another exception occurred:

Traceback (most recent call last):
  File "/easybuild/software/Python/3.10.8-GCCcore-12.2.0/lib/python3.10/asyncio/tasks.py", line 418, in wait_for
    return fut.result()
asyncio.exceptions.CancelledError

The above exception was the direct cause of the following exception:

Traceback (most recent call last):
  File "/home/shankaras1/.venv/lib/python3.10/site-packages/distributed/comm/core.py", line 329, in connect
    await asyncio.wait_for(comm.write(local_info), time_left())
  File "/easybuild/software/Python/3.10.8-GCCcore-12.2.0/lib/python3.10/asyncio/tasks.py", line 420, in wait_for
    raise exceptions.TimeoutError() from exc
asyncio.exceptions.TimeoutError

The above exception was the direct cause of the following exception:

Traceback (most recent call last):
  File "/home/shankaras1/.venv/lib/python3.10/site-packages/tornado/ioloop.py", line 741, in _run_callback
    ret = callback()
  File "/home/shankaras1/.venv/lib/python3.10/site-packages/tornado/ioloop.py", line 765, in _discard_future_result
    future.result()
  File "/home/shankaras1/.venv/lib/python3.10/site-packages/distributed/worker.py", line 1207, in heartbeat
    raise e
  File "/home/shankaras1/.venv/lib/python3.10/site-packages/distributed/worker.py", line 1161, in heartbeat
    response = await retry_operation(
  File "/home/shankaras1/.venv/lib/python3.10/site-packages/distributed/utils_comm.py", line 383, in retry_operation
    return await retry(
  File "/home/shankaras1/.venv/lib/python3.10/site-packages/distributed/utils_comm.py", line 368, in retry
    return await coro()
  File "/home/shankaras1/.venv/lib/python3.10/site-packages/distributed/core.py", line 1150, in send_recv_from_rpc
    comm = await self.pool.connect(self.addr)
  File "/home/shankaras1/.venv/lib/python3.10/site-packages/distributed/core.py", line 1371, in connect
    return await connect_attempt
  File "/home/shankaras1/.venv/lib/python3.10/site-packages/distributed/core.py", line 1307, in _connect
    comm = await connect(
  File "/home/shankaras1/.venv/lib/python3.10/site-packages/distributed/comm/core.py", line 333, in connect
    raise OSError(
OSError: Timed out during handshake while connecting to tcp://127.0.0.1:39719 after 30 s
omega = 0.000316835 finished in 42.95770734598045 seconds.
omega = 0.000318298 entered
2024-05-09 22:08:06,758 - tornado.application - ERROR - Exception in callback functools.partial(<bound method IOLoop._discard_future_result of <tornado.platform.asyncio.AsyncIOLoop object at 0x155548c28b20>>, <Task finished name='Task-16' coro=<Worker.heartbeat() done, defined at /home/shankaras1/.venv/lib/python3.10/site-packages/distributed/worker.py:1153> exception=OSError('Timed out during handshake while connecting to tcp://127.0.0.1:39719 after 30 s')>)
Traceback (most recent call last):
  File "/home/shankaras1/.venv/lib/python3.10/site-packages/distributed/comm/tcp.py", line 264, in write
    async def write(self, msg, serializers=None, on_error="message"):
asyncio.exceptions.CancelledError

During handling of the above exception, another exception occurred:

Traceback (most recent call last):
  File "/easybuild/software/Python/3.10.8-GCCcore-12.2.0/lib/python3.10/asyncio/tasks.py", line 418, in wait_for
    return fut.result()
asyncio.exceptions.CancelledError

The above exception was the direct cause of the following exception:

Traceback (most recent call last):
  File "/home/shankaras1/.venv/lib/python3.10/site-packages/distributed/comm/core.py", line 329, in connect
    await asyncio.wait_for(comm.write(local_info), time_left())
  File "/easybuild/software/Python/3.10.8-GCCcore-12.2.0/lib/python3.10/asyncio/tasks.py", line 420, in wait_for
    raise exceptions.TimeoutError() from exc
asyncio.exceptions.TimeoutError

The above exception was the direct cause of the following exception:

Traceback (most recent call last):
  File "/home/shankaras1/.venv/lib/python3.10/site-packages/tornado/ioloop.py", line 741, in _run_callback
    ret = callback()
  File "/home/shankaras1/.venv/lib/python3.10/site-packages/tornado/ioloop.py", line 765, in _discard_future_result
    future.result()
  File "/home/shankaras1/.venv/lib/python3.10/site-packages/distributed/worker.py", line 1207, in heartbeat
    raise e
  File "/home/shankaras1/.venv/lib/python3.10/site-packages/distributed/worker.py", line 1161, in heartbeat
    response = await retry_operation(
  File "/home/shankaras1/.venv/lib/python3.10/site-packages/distributed/utils_comm.py", line 383, in retry_operation
    return await retry(
  File "/home/shankaras1/.venv/lib/python3.10/site-packages/distributed/utils_comm.py", line 368, in retry
    return await coro()
  File "/home/shankaras1/.venv/lib/python3.10/site-packages/distributed/core.py", line 1150, in send_recv_from_rpc
    comm = await self.pool.connect(self.addr)
  File "/home/shankaras1/.venv/lib/python3.10/site-packages/distributed/core.py", line 1371, in connect
    return await connect_attempt
  File "/home/shankaras1/.venv/lib/python3.10/site-packages/distributed/core.py", line 1307, in _connect
    comm = await connect(
  File "/home/shankaras1/.venv/lib/python3.10/site-packages/distributed/comm/core.py", line 333, in connect
    raise OSError(
OSError: Timed out during handshake while connecting to tcp://127.0.0.1:39719 after 30 s
omega = 0.00056353 finished in 43.453827349003404 seconds.
2024-05-09 22:08:13,730 - distributed.worker - ERROR - Timed out during handshake while connecting to tcp://127.0.0.1:39719 after 30 s
Traceback (most recent call last):
  File "/home/shankaras1/.venv/lib/python3.10/site-packages/distributed/comm/tcp.py", line 264, in write
    async def write(self, msg, serializers=None, on_error="message"):
asyncio.exceptions.CancelledError

During handling of the above exception, another exception occurred:

Traceback (most recent call last):
  File "/easybuild/software/Python/3.10.8-GCCcore-12.2.0/lib/python3.10/asyncio/tasks.py", line 418, in wait_for
    return fut.result()
asyncio.exceptions.CancelledError

The above exception was the direct cause of the following exception:

Traceback (most recent call last):
  File "/home/shankaras1/.venv/lib/python3.10/site-packages/distributed/comm/core.py", line 329, in connect
    await asyncio.wait_for(comm.write(local_info), time_left())
  File "/easybuild/software/Python/3.10.8-GCCcore-12.2.0/lib/python3.10/asyncio/tasks.py", line 420, in wait_for
    raise exceptions.TimeoutError() from exc
asyncio.exceptions.TimeoutError

The above exception was the direct cause of the following exception:

Traceback (most recent call last):
  File "/home/shankaras1/.venv/lib/python3.10/site-packages/distributed/worker.py", line 1161, in heartbeat
    response = await retry_operation(
  File "/home/shankaras1/.venv/lib/python3.10/site-packages/distributed/utils_comm.py", line 383, in retry_operation
    return await retry(
  File "/home/shankaras1/.venv/lib/python3.10/site-packages/distributed/utils_comm.py", line 368, in retry
    return await coro()
  File "/home/shankaras1/.venv/lib/python3.10/site-packages/distributed/core.py", line 1150, in send_recv_from_rpc
    comm = await self.pool.connect(self.addr)
  File "/home/shankaras1/.venv/lib/python3.10/site-packages/distributed/core.py", line 1371, in connect
    return await connect_attempt
  File "/home/shankaras1/.venv/lib/python3.10/site-packages/distributed/core.py", line 1307, in _connect
    comm = await connect(
  File "/home/shankaras1/.venv/lib/python3.10/site-packages/distributed/comm/core.py", line 333, in connect
    raise OSError(
OSError: Timed out during handshake while connecting to tcp://127.0.0.1:39719 after 30 s
omega = 0.000566132 entered
2024-05-09 22:08:13,733 - tornado.application - ERROR - Exception in callback functools.partial(<bound method IOLoop._discard_future_result of <tornado.platform.asyncio.AsyncIOLoop object at 0x155548c28b20>>, <Task finished name='Task-16' coro=<Worker.heartbeat() done, defined at /home/shankaras1/.venv/lib/python3.10/site-packages/distributed/worker.py:1153> exception=OSError('Timed out during handshake while connecting to tcp://127.0.0.1:39719 after 30 s')>)
Traceback (most recent call last):
  File "/home/shankaras1/.venv/lib/python3.10/site-packages/distributed/comm/tcp.py", line 264, in write
    async def write(self, msg, serializers=None, on_error="message"):
asyncio.exceptions.CancelledError

During handling of the above exception, another exception occurred:

Traceback (most recent call last):
  File "/easybuild/software/Python/3.10.8-GCCcore-12.2.0/lib/python3.10/asyncio/tasks.py", line 418, in wait_for
    return fut.result()
asyncio.exceptions.CancelledError

The above exception was the direct cause of the following exception:

Traceback (most recent call last):
  File "/home/shankaras1/.venv/lib/python3.10/site-packages/distributed/comm/core.py", line 329, in connect
    await asyncio.wait_for(comm.write(local_info), time_left())
  File "/easybuild/software/Python/3.10.8-GCCcore-12.2.0/lib/python3.10/asyncio/tasks.py", line 420, in wait_for
    raise exceptions.TimeoutError() from exc
asyncio.exceptions.TimeoutError

The above exception was the direct cause of the following exception:

Traceback (most recent call last):
  File "/home/shankaras1/.venv/lib/python3.10/site-packages/tornado/ioloop.py", line 741, in _run_callback
    ret = callback()
  File "/home/shankaras1/.venv/lib/python3.10/site-packages/tornado/ioloop.py", line 765, in _discard_future_result
    future.result()
  File "/home/shankaras1/.venv/lib/python3.10/site-packages/distributed/worker.py", line 1207, in heartbeat
    raise e
  File "/home/shankaras1/.venv/lib/python3.10/site-packages/distributed/worker.py", line 1161, in heartbeat
    response = await retry_operation(
  File "/home/shankaras1/.venv/lib/python3.10/site-packages/distributed/utils_comm.py", line 383, in retry_operation
    return await retry(
  File "/home/shankaras1/.venv/lib/python3.10/site-packages/distributed/utils_comm.py", line 368, in retry
    return await coro()
  File "/home/shankaras1/.venv/lib/python3.10/site-packages/distributed/core.py", line 1150, in send_recv_from_rpc
    comm = await self.pool.connect(self.addr)
  File "/home/shankaras1/.venv/lib/python3.10/site-packages/distributed/core.py", line 1371, in connect
    return await connect_attempt
  File "/home/shankaras1/.venv/lib/python3.10/site-packages/distributed/core.py", line 1307, in _connect
    comm = await connect(
  File "/home/shankaras1/.venv/lib/python3.10/site-packages/distributed/comm/core.py", line 333, in connect
    raise OSError(
OSError: Timed out during handshake while connecting to tcp://127.0.0.1:39719 after 30 s
2024-05-09 22:08:09,398 - tornado.application - ERROR - Exception in callback functools.partial(<bound method IOLoop._discard_future_result of <tornado.platform.asyncio.AsyncIOLoop object at 0x155548c28b20>>, <Task finished name='Task-16' coro=<Worker.heartbeat() done, defined at /home/shankaras1/.venv/lib/python3.10/site-packages/distributed/worker.py:1153> exception=OSError('Timed out during handshake while connecting to tcp://127.0.0.1:39719 after 30 s')>)
Traceback (most recent call last):
  File "/home/shankaras1/.venv/lib/python3.10/site-packages/distributed/comm/tcp.py", line 264, in write
    async def write(self, msg, serializers=None, on_error="message"):
asyncio.exceptions.CancelledError

During handling of the above exception, another exception occurred:

Traceback (most recent call last):
  File "/easybuild/software/Python/3.10.8-GCCcore-12.2.0/lib/python3.10/asyncio/tasks.py", line 418, in wait_for
    return fut.result()
asyncio.exceptions.CancelledError

The above exception was the direct cause of the following exception:

Traceback (most recent call last):
  File "/home/shankaras1/.venv/lib/python3.10/site-packages/distributed/comm/core.py", line 329, in connect
    await asyncio.wait_for(comm.write(local_info), time_left())
  File "/easybuild/software/Python/3.10.8-GCCcore-12.2.0/lib/python3.10/asyncio/tasks.py", line 420, in wait_for
    raise exceptions.TimeoutError() from exc
asyncio.exceptions.TimeoutError

The above exception was the direct cause of the following exception:

Traceback (most recent call last):
  File "/home/shankaras1/.venv/lib/python3.10/site-packages/tornado/ioloop.py", line 741, in _run_callback
    ret = callback()
  File "/home/shankaras1/.venv/lib/python3.10/site-packages/tornado/ioloop.py", line 765, in _discard_future_result
    future.result()
  File "/home/shankaras1/.venv/lib/python3.10/site-packages/distributed/worker.py", line 1207, in heartbeat
    raise e
  File "/home/shankaras1/.venv/lib/python3.10/site-packages/distributed/worker.py", line 1161, in heartbeat
    response = await retry_operation(
  File "/home/shankaras1/.venv/lib/python3.10/site-packages/distributed/utils_comm.py", line 383, in retry_operation
    return await retry(
  File "/home/shankaras1/.venv/lib/python3.10/site-packages/distributed/utils_comm.py", line 368, in retry
    return await coro()
  File "/home/shankaras1/.venv/lib/python3.10/site-packages/distributed/core.py", line 1150, in send_recv_from_rpc
    comm = await self.pool.connect(self.addr)
  File "/home/shankaras1/.venv/lib/python3.10/site-packages/distributed/core.py", line 1371, in connect
    return await connect_attempt
  File "/home/shankaras1/.venv/lib/python3.10/site-packages/distributed/core.py", line 1307, in _connect
    comm = await connect(
  File "/home/shankaras1/.venv/lib/python3.10/site-packages/distributed/comm/core.py", line 333, in connect
    raise OSError(
OSError: Timed out during handshake while connecting to tcp://127.0.0.1:39719 after 30 s
2024-05-09 22:08:04,322 - distributed.worker - ERROR - Timed out during handshake while connecting to tcp://127.0.0.1:39719 after 30 s
Traceback (most recent call last):
  File "/home/shankaras1/.venv/lib/python3.10/site-packages/distributed/comm/tcp.py", line 264, in write
    async def write(self, msg, serializers=None, on_error="message"):
asyncio.exceptions.CancelledError

During handling of the above exception, another exception occurred:

Traceback (most recent call last):
  File "/easybuild/software/Python/3.10.8-GCCcore-12.2.0/lib/python3.10/asyncio/tasks.py", line 418, in wait_for
    return fut.result()
asyncio.exceptions.CancelledError

The above exception was the direct cause of the following exception:

Traceback (most recent call last):
  File "/home/shankaras1/.venv/lib/python3.10/site-packages/distributed/comm/core.py", line 329, in connect
    await asyncio.wait_for(comm.write(local_info), time_left())
  File "/easybuild/software/Python/3.10.8-GCCcore-12.2.0/lib/python3.10/asyncio/tasks.py", line 420, in wait_for
    raise exceptions.TimeoutError() from exc
asyncio.exceptions.TimeoutError

The above exception was the direct cause of the following exception:

Traceback (most recent call last):
  File "/home/shankaras1/.venv/lib/python3.10/site-packages/distributed/worker.py", line 1161, in heartbeat
    response = await retry_operation(
  File "/home/shankaras1/.venv/lib/python3.10/site-packages/distributed/utils_comm.py", line 383, in retry_operation
    return await retry(
  File "/home/shankaras1/.venv/lib/python3.10/site-packages/distributed/utils_comm.py", line 368, in retry
    return await coro()
  File "/home/shankaras1/.venv/lib/python3.10/site-packages/distributed/core.py", line 1150, in send_recv_from_rpc
    comm = await self.pool.connect(self.addr)
  File "/home/shankaras1/.venv/lib/python3.10/site-packages/distributed/core.py", line 1371, in connect
    return await connect_attempt
  File "/home/shankaras1/.venv/lib/python3.10/site-packages/distributed/core.py", line 1307, in _connect
    comm = await connect(
  File "/home/shankaras1/.venv/lib/python3.10/site-packages/distributed/comm/core.py", line 333, in connect
    raise OSError(
OSError: Timed out during handshake while connecting to tcp://127.0.0.1:39719 after 30 s
2024-05-09 22:08:11,064 - tornado.application - ERROR - Exception in callback functools.partial(<bound method IOLoop._discard_future_result of <tornado.platform.asyncio.AsyncIOLoop object at 0x155548c28b20>>, <Task finished name='Task-16' coro=<Worker.heartbeat() done, defined at /home/shankaras1/.venv/lib/python3.10/site-packages/distributed/worker.py:1153> exception=OSError('Timed out during handshake while connecting to tcp://127.0.0.1:39719 after 30 s')>)
Traceback (most recent call last):
  File "/home/shankaras1/.venv/lib/python3.10/site-packages/distributed/comm/tcp.py", line 264, in write
    async def write(self, msg, serializers=None, on_error="message"):
asyncio.exceptions.CancelledError

During handling of the above exception, another exception occurred:

Traceback (most recent call last):
  File "/easybuild/software/Python/3.10.8-GCCcore-12.2.0/lib/python3.10/asyncio/tasks.py", line 418, in wait_for
    return fut.result()
asyncio.exceptions.CancelledError

The above exception was the direct cause of the following exception:

Traceback (most recent call last):
  File "/home/shankaras1/.venv/lib/python3.10/site-packages/distributed/comm/core.py", line 329, in connect
    await asyncio.wait_for(comm.write(local_info), time_left())
  File "/easybuild/software/Python/3.10.8-GCCcore-12.2.0/lib/python3.10/asyncio/tasks.py", line 420, in wait_for
    raise exceptions.TimeoutError() from exc
asyncio.exceptions.TimeoutError

The above exception was the direct cause of the following exception:

Traceback (most recent call last):
  File "/home/shankaras1/.venv/lib/python3.10/site-packages/tornado/ioloop.py", line 741, in _run_callback
    ret = callback()
  File "/home/shankaras1/.venv/lib/python3.10/site-packages/tornado/ioloop.py", line 765, in _discard_future_result
    future.result()
  File "/home/shankaras1/.venv/lib/python3.10/site-packages/distributed/worker.py", line 1207, in heartbeat
    raise e
  File "/home/shankaras1/.venv/lib/python3.10/site-packages/distributed/worker.py", line 1161, in heartbeat
    response = await retry_operation(
  File "/home/shankaras1/.venv/lib/python3.10/site-packages/distributed/utils_comm.py", line 383, in retry_operation
    return await retry(
  File "/home/shankaras1/.venv/lib/python3.10/site-packages/distributed/utils_comm.py", line 368, in retry
    return await coro()
  File "/home/shankaras1/.venv/lib/python3.10/site-packages/distributed/core.py", line 1150, in send_recv_from_rpc
    comm = await self.pool.connect(self.addr)
  File "/home/shankaras1/.venv/lib/python3.10/site-packages/distributed/core.py", line 1371, in connect
    return await connect_attempt
  File "/home/shankaras1/.venv/lib/python3.10/site-packages/distributed/core.py", line 1307, in _connect
    comm = await connect(
  File "/home/shankaras1/.venv/lib/python3.10/site-packages/distributed/comm/core.py", line 333, in connect
    raise OSError(
OSError: Timed out during handshake while connecting to tcp://127.0.0.1:39719 after 30 s
2024-05-09 22:08:10,818 - tornado.application - ERROR - Exception in callback functools.partial(<bound method IOLoop._discard_future_result of <tornado.platform.asyncio.AsyncIOLoop object at 0x155548c28b20>>, <Task finished name='Task-16' coro=<Worker.heartbeat() done, defined at /home/shankaras1/.venv/lib/python3.10/site-packages/distributed/worker.py:1153> exception=OSError('Timed out during handshake while connecting to tcp://127.0.0.1:39719 after 30 s')>)
Traceback (most recent call last):
  File "/home/shankaras1/.venv/lib/python3.10/site-packages/distributed/comm/tcp.py", line 264, in write
    async def write(self, msg, serializers=None, on_error="message"):
asyncio.exceptions.CancelledError

During handling of the above exception, another exception occurred:

Traceback (most recent call last):
  File "/easybuild/software/Python/3.10.8-GCCcore-12.2.0/lib/python3.10/asyncio/tasks.py", line 418, in wait_for
    return fut.result()
asyncio.exceptions.CancelledError

The above exception was the direct cause of the following exception:

Traceback (most recent call last):
  File "/home/shankaras1/.venv/lib/python3.10/site-packages/distributed/comm/core.py", line 329, in connect
    await asyncio.wait_for(comm.write(local_info), time_left())
  File "/easybuild/software/Python/3.10.8-GCCcore-12.2.0/lib/python3.10/asyncio/tasks.py", line 420, in wait_for
    raise exceptions.TimeoutError() from exc
asyncio.exceptions.TimeoutError

The above exception was the direct cause of the following exception:

Traceback (most recent call last):
  File "/home/shankaras1/.venv/lib/python3.10/site-packages/tornado/ioloop.py", line 741, in _run_callback
    ret = callback()
  File "/home/shankaras1/.venv/lib/python3.10/site-packages/tornado/ioloop.py", line 765, in _discard_future_result
    future.result()
  File "/home/shankaras1/.venv/lib/python3.10/site-packages/distributed/worker.py", line 1207, in heartbeat
    raise e
  File "/home/shankaras1/.venv/lib/python3.10/site-packages/distributed/worker.py", line 1161, in heartbeat
    response = await retry_operation(
  File "/home/shankaras1/.venv/lib/python3.10/site-packages/distributed/utils_comm.py", line 383, in retry_operation
    return await retry(
  File "/home/shankaras1/.venv/lib/python3.10/site-packages/distributed/utils_comm.py", line 368, in retry
    return await coro()
  File "/home/shankaras1/.venv/lib/python3.10/site-packages/distributed/core.py", line 1150, in send_recv_from_rpc
    comm = await self.pool.connect(self.addr)
  File "/home/shankaras1/.venv/lib/python3.10/site-packages/distributed/core.py", line 1371, in connect
    return await connect_attempt
  File "/home/shankaras1/.venv/lib/python3.10/site-packages/distributed/core.py", line 1307, in _connect
    comm = await connect(
  File "/home/shankaras1/.venv/lib/python3.10/site-packages/distributed/comm/core.py", line 333, in connect
    raise OSError(
OSError: Timed out during handshake while connecting to tcp://127.0.0.1:39719 after 30 s
2024-05-09 22:08:10,740 - distributed.worker - ERROR - Timed out during handshake while connecting to tcp://127.0.0.1:39719 after 30 s
Traceback (most recent call last):
  File "/home/shankaras1/.venv/lib/python3.10/site-packages/distributed/comm/tcp.py", line 264, in write
    async def write(self, msg, serializers=None, on_error="message"):
asyncio.exceptions.CancelledError

During handling of the above exception, another exception occurred:

Traceback (most recent call last):
  File "/easybuild/software/Python/3.10.8-GCCcore-12.2.0/lib/python3.10/asyncio/tasks.py", line 418, in wait_for
    return fut.result()
asyncio.exceptions.CancelledError

The above exception was the direct cause of the following exception:

Traceback (most recent call last):
  File "/home/shankaras1/.venv/lib/python3.10/site-packages/distributed/comm/core.py", line 329, in connect
    await asyncio.wait_for(comm.write(local_info), time_left())
  File "/easybuild/software/Python/3.10.8-GCCcore-12.2.0/lib/python3.10/asyncio/tasks.py", line 420, in wait_for
    raise exceptions.TimeoutError() from exc
asyncio.exceptions.TimeoutError

The above exception was the direct cause of the following exception:

Traceback (most recent call last):
  File "/home/shankaras1/.venv/lib/python3.10/site-packages/distributed/worker.py", line 1161, in heartbeat
    response = await retry_operation(
  File "/home/shankaras1/.venv/lib/python3.10/site-packages/distributed/utils_comm.py", line 383, in retry_operation
    return await retry(
  File "/home/shankaras1/.venv/lib/python3.10/site-packages/distributed/utils_comm.py", line 368, in retry
    return await coro()
  File "/home/shankaras1/.venv/lib/python3.10/site-packages/distributed/core.py", line 1150, in send_recv_from_rpc
    comm = await self.pool.connect(self.addr)
  File "/home/shankaras1/.venv/lib/python3.10/site-packages/distributed/core.py", line 1371, in connect
    return await connect_attempt
  File "/home/shankaras1/.venv/lib/python3.10/site-packages/distributed/core.py", line 1307, in _connect
    comm = await connect(
  File "/home/shankaras1/.venv/lib/python3.10/site-packages/distributed/comm/core.py", line 333, in connect
    raise OSError(
OSError: Timed out during handshake while connecting to tcp://127.0.0.1:39719 after 30 s
2024-05-09 22:08:04,683 - distributed.worker - ERROR - Timed out during handshake while connecting to tcp://127.0.0.1:39719 after 30 s
Traceback (most recent call last):
  File "/home/shankaras1/.venv/lib/python3.10/site-packages/distributed/comm/tcp.py", line 264, in write
    async def write(self, msg, serializers=None, on_error="message"):
asyncio.exceptions.CancelledError

During handling of the above exception, another exception occurred:

Traceback (most recent call last):
  File "/easybuild/software/Python/3.10.8-GCCcore-12.2.0/lib/python3.10/asyncio/tasks.py", line 418, in wait_for
    return fut.result()
asyncio.exceptions.CancelledError

The above exception was the direct cause of the following exception:

Traceback (most recent call last):
  File "/home/shankaras1/.venv/lib/python3.10/site-packages/distributed/comm/core.py", line 329, in connect
    await asyncio.wait_for(comm.write(local_info), time_left())
  File "/easybuild/software/Python/3.10.8-GCCcore-12.2.0/lib/python3.10/asyncio/tasks.py", line 420, in wait_for
    raise exceptions.TimeoutError() from exc
asyncio.exceptions.TimeoutError

The above exception was the direct cause of the following exception:

Traceback (most recent call last):
  File "/home/shankaras1/.venv/lib/python3.10/site-packages/distributed/worker.py", line 1161, in heartbeat
    response = await retry_operation(
  File "/home/shankaras1/.venv/lib/python3.10/site-packages/distributed/utils_comm.py", line 383, in retry_operation
    return await retry(
  File "/home/shankaras1/.venv/lib/python3.10/site-packages/distributed/utils_comm.py", line 368, in retry
    return await coro()
  File "/home/shankaras1/.venv/lib/python3.10/site-packages/distributed/core.py", line 1150, in send_recv_from_rpc
    comm = await self.pool.connect(self.addr)
  File "/home/shankaras1/.venv/lib/python3.10/site-packages/distributed/core.py", line 1371, in connect
    return await connect_attempt
  File "/home/shankaras1/.venv/lib/python3.10/site-packages/distributed/core.py", line 1307, in _connect
    comm = await connect(
  File "/home/shankaras1/.venv/lib/python3.10/site-packages/distributed/comm/core.py", line 333, in connect
    raise OSError(
OSError: Timed out during handshake while connecting to tcp://127.0.0.1:39719 after 30 s
2024-05-09 22:08:05,288 - distributed.worker - ERROR - Timed out during handshake while connecting to tcp://127.0.0.1:39719 after 30 s
Traceback (most recent call last):
  File "/home/shankaras1/.venv/lib/python3.10/site-packages/distributed/comm/tcp.py", line 264, in write
    async def write(self, msg, serializers=None, on_error="message"):
asyncio.exceptions.CancelledError

During handling of the above exception, another exception occurred:

Traceback (most recent call last):
  File "/easybuild/software/Python/3.10.8-GCCcore-12.2.0/lib/python3.10/asyncio/tasks.py", line 418, in wait_for
    return fut.result()
asyncio.exceptions.CancelledError

The above exception was the direct cause of the following exception:

Traceback (most recent call last):
  File "/home/shankaras1/.venv/lib/python3.10/site-packages/distributed/comm/core.py", line 329, in connect
    await asyncio.wait_for(comm.write(local_info), time_left())
  File "/easybuild/software/Python/3.10.8-GCCcore-12.2.0/lib/python3.10/asyncio/tasks.py", line 420, in wait_for
    raise exceptions.TimeoutError() from exc
asyncio.exceptions.TimeoutError

The above exception was the direct cause of the following exception:

Traceback (most recent call last):
  File "/home/shankaras1/.venv/lib/python3.10/site-packages/distributed/worker.py", line 1161, in heartbeat
    response = await retry_operation(
  File "/home/shankaras1/.venv/lib/python3.10/site-packages/distributed/utils_comm.py", line 383, in retry_operation
    return await retry(
  File "/home/shankaras1/.venv/lib/python3.10/site-packages/distributed/utils_comm.py", line 368, in retry
    return await coro()
  File "/home/shankaras1/.venv/lib/python3.10/site-packages/distributed/core.py", line 1150, in send_recv_from_rpc
    comm = await self.pool.connect(self.addr)
  File "/home/shankaras1/.venv/lib/python3.10/site-packages/distributed/core.py", line 1371, in connect
    return await connect_attempt
  File "/home/shankaras1/.venv/lib/python3.10/site-packages/distributed/core.py", line 1307, in _connect
    comm = await connect(
  File "/home/shankaras1/.venv/lib/python3.10/site-packages/distributed/comm/core.py", line 333, in connect
    raise OSError(
OSError: Timed out during handshake while connecting to tcp://127.0.0.1:39719 after 30 s
2024-05-09 22:08:11,277 - distributed.worker - ERROR - Timed out during handshake while connecting to tcp://127.0.0.1:39719 after 30 s
Traceback (most recent call last):
  File "/home/shankaras1/.venv/lib/python3.10/site-packages/distributed/comm/tcp.py", line 264, in write
    async def write(self, msg, serializers=None, on_error="message"):
asyncio.exceptions.CancelledError

During handling of the above exception, another exception occurred:

Traceback (most recent call last):
  File "/easybuild/software/Python/3.10.8-GCCcore-12.2.0/lib/python3.10/asyncio/tasks.py", line 418, in wait_for
    return fut.result()
asyncio.exceptions.CancelledError

The above exception was the direct cause of the following exception:

Traceback (most recent call last):
  File "/home/shankaras1/.venv/lib/python3.10/site-packages/distributed/comm/core.py", line 329, in connect
    await asyncio.wait_for(comm.write(local_info), time_left())
  File "/easybuild/software/Python/3.10.8-GCCcore-12.2.0/lib/python3.10/asyncio/tasks.py", line 420, in wait_for
    raise exceptions.TimeoutError() from exc
asyncio.exceptions.TimeoutError

The above exception was the direct cause of the following exception:

Traceback (most recent call last):
  File "/home/shankaras1/.venv/lib/python3.10/site-packages/distributed/worker.py", line 1161, in heartbeat
    response = await retry_operation(
  File "/home/shankaras1/.venv/lib/python3.10/site-packages/distributed/utils_comm.py", line 383, in retry_operation
    return await retry(
  File "/home/shankaras1/.venv/lib/python3.10/site-packages/distributed/utils_comm.py", line 368, in retry
    return await coro()
  File "/home/shankaras1/.venv/lib/python3.10/site-packages/distributed/core.py", line 1150, in send_recv_from_rpc
    comm = await self.pool.connect(self.addr)
  File "/home/shankaras1/.venv/lib/python3.10/site-packages/distributed/core.py", line 1371, in connect
    return await connect_attempt
  File "/home/shankaras1/.venv/lib/python3.10/site-packages/distributed/core.py", line 1307, in _connect
    comm = await connect(
  File "/home/shankaras1/.venv/lib/python3.10/site-packages/distributed/comm/core.py", line 333, in connect
    raise OSError(
OSError: Timed out during handshake while connecting to tcp://127.0.0.1:39719 after 30 s
2024-05-09 22:08:15,946 - tornado.application - ERROR - Exception in callback functools.partial(<bound method IOLoop._discard_future_result of <tornado.platform.asyncio.AsyncIOLoop object at 0x155548c28b20>>, <Task finished name='Task-16' coro=<Worker.heartbeat() done, defined at /home/shankaras1/.venv/lib/python3.10/site-packages/distributed/worker.py:1153> exception=OSError('Timed out during handshake while connecting to tcp://127.0.0.1:39719 after 30 s')>)
Traceback (most recent call last):
  File "/home/shankaras1/.venv/lib/python3.10/site-packages/distributed/comm/tcp.py", line 264, in write
    async def write(self, msg, serializers=None, on_error="message"):
asyncio.exceptions.CancelledError

During handling of the above exception, another exception occurred:

Traceback (most recent call last):
  File "/easybuild/software/Python/3.10.8-GCCcore-12.2.0/lib/python3.10/asyncio/tasks.py", line 418, in wait_for
    return fut.result()
asyncio.exceptions.CancelledError

The above exception was the direct cause of the following exception:

Traceback (most recent call last):
  File "/home/shankaras1/.venv/lib/python3.10/site-packages/distributed/comm/core.py", line 329, in connect
    await asyncio.wait_for(comm.write(local_info), time_left())
  File "/easybuild/software/Python/3.10.8-GCCcore-12.2.0/lib/python3.10/asyncio/tasks.py", line 420, in wait_for
    raise exceptions.TimeoutError() from exc
asyncio.exceptions.TimeoutError

The above exception was the direct cause of the following exception:

Traceback (most recent call last):
  File "/home/shankaras1/.venv/lib/python3.10/site-packages/tornado/ioloop.py", line 741, in _run_callback
    ret = callback()
  File "/home/shankaras1/.venv/lib/python3.10/site-packages/tornado/ioloop.py", line 765, in _discard_future_result
    future.result()
  File "/home/shankaras1/.venv/lib/python3.10/site-packages/distributed/worker.py", line 1207, in heartbeat
    raise e
  File "/home/shankaras1/.venv/lib/python3.10/site-packages/distributed/worker.py", line 1161, in heartbeat
    response = await retry_operation(
  File "/home/shankaras1/.venv/lib/python3.10/site-packages/distributed/utils_comm.py", line 383, in retry_operation
    return await retry(
  File "/home/shankaras1/.venv/lib/python3.10/site-packages/distributed/utils_comm.py", line 368, in retry
    return await coro()
  File "/home/shankaras1/.venv/lib/python3.10/site-packages/distributed/core.py", line 1150, in send_recv_from_rpc
    comm = await self.pool.connect(self.addr)
  File "/home/shankaras1/.venv/lib/python3.10/site-packages/distributed/core.py", line 1371, in connect
    return await connect_attempt
  File "/home/shankaras1/.venv/lib/python3.10/site-packages/distributed/core.py", line 1307, in _connect
    comm = await connect(
  File "/home/shankaras1/.venv/lib/python3.10/site-packages/distributed/comm/core.py", line 333, in connect
    raise OSError(
OSError: Timed out during handshake while connecting to tcp://127.0.0.1:39719 after 30 s
2024-05-09 22:08:10,239 - tornado.application - ERROR - Exception in callback functools.partial(<bound method IOLoop._discard_future_result of <tornado.platform.asyncio.AsyncIOLoop object at 0x155548c28b20>>, <Task finished name='Task-16' coro=<Worker.heartbeat() done, defined at /home/shankaras1/.venv/lib/python3.10/site-packages/distributed/worker.py:1153> exception=OSError('Timed out during handshake while connecting to tcp://127.0.0.1:39719 after 30 s')>)
Traceback (most recent call last):
  File "/home/shankaras1/.venv/lib/python3.10/site-packages/distributed/comm/tcp.py", line 264, in write
    async def write(self, msg, serializers=None, on_error="message"):
asyncio.exceptions.CancelledError

During handling of the above exception, another exception occurred:

Traceback (most recent call last):
  File "/easybuild/software/Python/3.10.8-GCCcore-12.2.0/lib/python3.10/asyncio/tasks.py", line 418, in wait_for
    return fut.result()
asyncio.exceptions.CancelledError

The above exception was the direct cause of the following exception:

Traceback (most recent call last):
  File "/home/shankaras1/.venv/lib/python3.10/site-packages/distributed/comm/core.py", line 329, in connect
    await asyncio.wait_for(comm.write(local_info), time_left())
  File "/easybuild/software/Python/3.10.8-GCCcore-12.2.0/lib/python3.10/asyncio/tasks.py", line 420, in wait_for
    raise exceptions.TimeoutError() from exc
asyncio.exceptions.TimeoutError

The above exception was the direct cause of the following exception:

Traceback (most recent call last):
  File "/home/shankaras1/.venv/lib/python3.10/site-packages/tornado/ioloop.py", line 741, in _run_callback
    ret = callback()
  File "/home/shankaras1/.venv/lib/python3.10/site-packages/tornado/ioloop.py", line 765, in _discard_future_result
    future.result()
  File "/home/shankaras1/.venv/lib/python3.10/site-packages/distributed/worker.py", line 1207, in heartbeat
    raise e
  File "/home/shankaras1/.venv/lib/python3.10/site-packages/distributed/worker.py", line 1161, in heartbeat
    response = await retry_operation(
  File "/home/shankaras1/.venv/lib/python3.10/site-packages/distributed/utils_comm.py", line 383, in retry_operation
    return await retry(
  File "/home/shankaras1/.venv/lib/python3.10/site-packages/distributed/utils_comm.py", line 368, in retry
    return await coro()
  File "/home/shankaras1/.venv/lib/python3.10/site-packages/distributed/core.py", line 1150, in send_recv_from_rpc
    comm = await self.pool.connect(self.addr)
  File "/home/shankaras1/.venv/lib/python3.10/site-packages/distributed/core.py", line 1371, in connect
    return await connect_attempt
  File "/home/shankaras1/.venv/lib/python3.10/site-packages/distributed/core.py", line 1307, in _connect
    comm = await connect(
  File "/home/shankaras1/.venv/lib/python3.10/site-packages/distributed/comm/core.py", line 333, in connect
    raise OSError(
OSError: Timed out during handshake while connecting to tcp://127.0.0.1:39719 after 30 s
2024-05-09 22:08:16,169 - tornado.application - ERROR - Exception in callback functools.partial(<bound method IOLoop._discard_future_result of <tornado.platform.asyncio.AsyncIOLoop object at 0x155548c28b20>>, <Task finished name='Task-16' coro=<Worker.heartbeat() done, defined at /home/shankaras1/.venv/lib/python3.10/site-packages/distributed/worker.py:1153> exception=OSError('Timed out during handshake while connecting to tcp://127.0.0.1:39719 after 30 s')>)
Traceback (most recent call last):
  File "/home/shankaras1/.venv/lib/python3.10/site-packages/distributed/comm/tcp.py", line 264, in write
    async def write(self, msg, serializers=None, on_error="message"):
asyncio.exceptions.CancelledError

During handling of the above exception, another exception occurred:

Traceback (most recent call last):
  File "/easybuild/software/Python/3.10.8-GCCcore-12.2.0/lib/python3.10/asyncio/tasks.py", line 418, in wait_for
    return fut.result()
asyncio.exceptions.CancelledError

The above exception was the direct cause of the following exception:

Traceback (most recent call last):
  File "/home/shankaras1/.venv/lib/python3.10/site-packages/distributed/comm/core.py", line 329, in connect
    await asyncio.wait_for(comm.write(local_info), time_left())
  File "/easybuild/software/Python/3.10.8-GCCcore-12.2.0/lib/python3.10/asyncio/tasks.py", line 420, in wait_for
    raise exceptions.TimeoutError() from exc
asyncio.exceptions.TimeoutError

The above exception was the direct cause of the following exception:

Traceback (most recent call last):
  File "/home/shankaras1/.venv/lib/python3.10/site-packages/tornado/ioloop.py", line 741, in _run_callback
    ret = callback()
  File "/home/shankaras1/.venv/lib/python3.10/site-packages/tornado/ioloop.py", line 765, in _discard_future_result
    future.result()
  File "/home/shankaras1/.venv/lib/python3.10/site-packages/distributed/worker.py", line 1207, in heartbeat
    raise e
  File "/home/shankaras1/.venv/lib/python3.10/site-packages/distributed/worker.py", line 1161, in heartbeat
    response = await retry_operation(
  File "/home/shankaras1/.venv/lib/python3.10/site-packages/distributed/utils_comm.py", line 383, in retry_operation
    return await retry(
  File "/home/shankaras1/.venv/lib/python3.10/site-packages/distributed/utils_comm.py", line 368, in retry
    return await coro()
  File "/home/shankaras1/.venv/lib/python3.10/site-packages/distributed/core.py", line 1150, in send_recv_from_rpc
    comm = await self.pool.connect(self.addr)
  File "/home/shankaras1/.venv/lib/python3.10/site-packages/distributed/core.py", line 1371, in connect
    return await connect_attempt
  File "/home/shankaras1/.venv/lib/python3.10/site-packages/distributed/core.py", line 1307, in _connect
    comm = await connect(
  File "/home/shankaras1/.venv/lib/python3.10/site-packages/distributed/comm/core.py", line 333, in connect
    raise OSError(
OSError: Timed out during handshake while connecting to tcp://127.0.0.1:39719 after 30 s
2024-05-09 22:08:11,577 - distributed.worker - ERROR - Timed out during handshake while connecting to tcp://127.0.0.1:39719 after 30 s
Traceback (most recent call last):
  File "/home/shankaras1/.venv/lib/python3.10/site-packages/distributed/comm/tcp.py", line 264, in write
    async def write(self, msg, serializers=None, on_error="message"):
asyncio.exceptions.CancelledError

During handling of the above exception, another exception occurred:

Traceback (most recent call last):
  File "/easybuild/software/Python/3.10.8-GCCcore-12.2.0/lib/python3.10/asyncio/tasks.py", line 418, in wait_for
    return fut.result()
asyncio.exceptions.CancelledError

The above exception was the direct cause of the following exception:

Traceback (most recent call last):
  File "/home/shankaras1/.venv/lib/python3.10/site-packages/distributed/comm/core.py", line 329, in connect
    await asyncio.wait_for(comm.write(local_info), time_left())
  File "/easybuild/software/Python/3.10.8-GCCcore-12.2.0/lib/python3.10/asyncio/tasks.py", line 420, in wait_for
    raise exceptions.TimeoutError() from exc
asyncio.exceptions.TimeoutError

The above exception was the direct cause of the following exception:

Traceback (most recent call last):
  File "/home/shankaras1/.venv/lib/python3.10/site-packages/distributed/worker.py", line 1161, in heartbeat
    response = await retry_operation(
  File "/home/shankaras1/.venv/lib/python3.10/site-packages/distributed/utils_comm.py", line 383, in retry_operation
    return await retry(
  File "/home/shankaras1/.venv/lib/python3.10/site-packages/distributed/utils_comm.py", line 368, in retry
    return await coro()
  File "/home/shankaras1/.venv/lib/python3.10/site-packages/distributed/core.py", line 1150, in send_recv_from_rpc
    comm = await self.pool.connect(self.addr)
  File "/home/shankaras1/.venv/lib/python3.10/site-packages/distributed/core.py", line 1371, in connect
    return await connect_attempt
  File "/home/shankaras1/.venv/lib/python3.10/site-packages/distributed/core.py", line 1307, in _connect
    comm = await connect(
  File "/home/shankaras1/.venv/lib/python3.10/site-packages/distributed/comm/core.py", line 333, in connect
    raise OSError(
OSError: Timed out during handshake while connecting to tcp://127.0.0.1:39719 after 30 s
2024-05-09 22:08:14,356 - tornado.application - ERROR - Exception in callback functools.partial(<bound method IOLoop._discard_future_result of <tornado.platform.asyncio.AsyncIOLoop object at 0x155548c28b20>>, <Task finished name='Task-16' coro=<Worker.heartbeat() done, defined at /home/shankaras1/.venv/lib/python3.10/site-packages/distributed/worker.py:1153> exception=OSError('Timed out during handshake while connecting to tcp://127.0.0.1:39719 after 30 s')>)
Traceback (most recent call last):
  File "/home/shankaras1/.venv/lib/python3.10/site-packages/distributed/comm/tcp.py", line 264, in write
    async def write(self, msg, serializers=None, on_error="message"):
asyncio.exceptions.CancelledError

During handling of the above exception, another exception occurred:

Traceback (most recent call last):
  File "/easybuild/software/Python/3.10.8-GCCcore-12.2.0/lib/python3.10/asyncio/tasks.py", line 418, in wait_for
    return fut.result()
asyncio.exceptions.CancelledError

The above exception was the direct cause of the following exception:

Traceback (most recent call last):
  File "/home/shankaras1/.venv/lib/python3.10/site-packages/distributed/comm/core.py", line 329, in connect
    await asyncio.wait_for(comm.write(local_info), time_left())
  File "/easybuild/software/Python/3.10.8-GCCcore-12.2.0/lib/python3.10/asyncio/tasks.py", line 420, in wait_for
    raise exceptions.TimeoutError() from exc
asyncio.exceptions.TimeoutError

The above exception was the direct cause of the following exception:

Traceback (most recent call last):
  File "/home/shankaras1/.venv/lib/python3.10/site-packages/tornado/ioloop.py", line 741, in _run_callback
    ret = callback()
  File "/home/shankaras1/.venv/lib/python3.10/site-packages/tornado/ioloop.py", line 765, in _discard_future_result
    future.result()
  File "/home/shankaras1/.venv/lib/python3.10/site-packages/distributed/worker.py", line 1207, in heartbeat
    raise e
  File "/home/shankaras1/.venv/lib/python3.10/site-packages/distributed/worker.py", line 1161, in heartbeat
    response = await retry_operation(
  File "/home/shankaras1/.venv/lib/python3.10/site-packages/distributed/utils_comm.py", line 383, in retry_operation
    return await retry(
  File "/home/shankaras1/.venv/lib/python3.10/site-packages/distributed/utils_comm.py", line 368, in retry
    return await coro()
  File "/home/shankaras1/.venv/lib/python3.10/site-packages/distributed/core.py", line 1150, in send_recv_from_rpc
    comm = await self.pool.connect(self.addr)
  File "/home/shankaras1/.venv/lib/python3.10/site-packages/distributed/core.py", line 1371, in connect
    return await connect_attempt
  File "/home/shankaras1/.venv/lib/python3.10/site-packages/distributed/core.py", line 1307, in _connect
    comm = await connect(
  File "/home/shankaras1/.venv/lib/python3.10/site-packages/distributed/comm/core.py", line 333, in connect
    raise OSError(
OSError: Timed out during handshake while connecting to tcp://127.0.0.1:39719 after 30 s
2024-05-09 22:08:13,234 - distributed.worker - ERROR - Timed out during handshake while connecting to tcp://127.0.0.1:39719 after 30 s
Traceback (most recent call last):
  File "/home/shankaras1/.venv/lib/python3.10/site-packages/distributed/comm/tcp.py", line 264, in write
    async def write(self, msg, serializers=None, on_error="message"):
asyncio.exceptions.CancelledError

During handling of the above exception, another exception occurred:

Traceback (most recent call last):
  File "/easybuild/software/Python/3.10.8-GCCcore-12.2.0/lib/python3.10/asyncio/tasks.py", line 418, in wait_for
    return fut.result()
asyncio.exceptions.CancelledError

The above exception was the direct cause of the following exception:

Traceback (most recent call last):
  File "/home/shankaras1/.venv/lib/python3.10/site-packages/distributed/comm/core.py", line 329, in connect
    await asyncio.wait_for(comm.write(local_info), time_left())
  File "/easybuild/software/Python/3.10.8-GCCcore-12.2.0/lib/python3.10/asyncio/tasks.py", line 420, in wait_for
    raise exceptions.TimeoutError() from exc
asyncio.exceptions.TimeoutError

The above exception was the direct cause of the following exception:

Traceback (most recent call last):
  File "/home/shankaras1/.venv/lib/python3.10/site-packages/distributed/worker.py", line 1161, in heartbeat
    response = await retry_operation(
  File "/home/shankaras1/.venv/lib/python3.10/site-packages/distributed/utils_comm.py", line 383, in retry_operation
    return await retry(
  File "/home/shankaras1/.venv/lib/python3.10/site-packages/distributed/utils_comm.py", line 368, in retry
    return await coro()
  File "/home/shankaras1/.venv/lib/python3.10/site-packages/distributed/core.py", line 1150, in send_recv_from_rpc
    comm = await self.pool.connect(self.addr)
  File "/home/shankaras1/.venv/lib/python3.10/site-packages/distributed/core.py", line 1371, in connect
    return await connect_attempt
  File "/home/shankaras1/.venv/lib/python3.10/site-packages/distributed/core.py", line 1307, in _connect
    comm = await connect(
  File "/home/shankaras1/.venv/lib/python3.10/site-packages/distributed/comm/core.py", line 333, in connect
    raise OSError(
OSError: Timed out during handshake while connecting to tcp://127.0.0.1:39719 after 30 s
2024-05-09 22:08:15,652 - tornado.application - ERROR - Exception in callback functools.partial(<bound method IOLoop._discard_future_result of <tornado.platform.asyncio.AsyncIOLoop object at 0x155548c28b20>>, <Task finished name='Task-16' coro=<Worker.heartbeat() done, defined at /home/shankaras1/.venv/lib/python3.10/site-packages/distributed/worker.py:1153> exception=OSError('Timed out during handshake while connecting to tcp://127.0.0.1:39719 after 30 s')>)
Traceback (most recent call last):
  File "/home/shankaras1/.venv/lib/python3.10/site-packages/distributed/comm/tcp.py", line 264, in write
    async def write(self, msg, serializers=None, on_error="message"):
asyncio.exceptions.CancelledError

During handling of the above exception, another exception occurred:

Traceback (most recent call last):
  File "/easybuild/software/Python/3.10.8-GCCcore-12.2.0/lib/python3.10/asyncio/tasks.py", line 418, in wait_for
    return fut.result()
asyncio.exceptions.CancelledError

The above exception was the direct cause of the following exception:

Traceback (most recent call last):
  File "/home/shankaras1/.venv/lib/python3.10/site-packages/distributed/comm/core.py", line 329, in connect
    await asyncio.wait_for(comm.write(local_info), time_left())
  File "/easybuild/software/Python/3.10.8-GCCcore-12.2.0/lib/python3.10/asyncio/tasks.py", line 420, in wait_for
    raise exceptions.TimeoutError() from exc
asyncio.exceptions.TimeoutError

The above exception was the direct cause of the following exception:

Traceback (most recent call last):
  File "/home/shankaras1/.venv/lib/python3.10/site-packages/tornado/ioloop.py", line 741, in _run_callback
    ret = callback()
  File "/home/shankaras1/.venv/lib/python3.10/site-packages/tornado/ioloop.py", line 765, in _discard_future_result
    future.result()
  File "/home/shankaras1/.venv/lib/python3.10/site-packages/distributed/worker.py", line 1207, in heartbeat
    raise e
  File "/home/shankaras1/.venv/lib/python3.10/site-packages/distributed/worker.py", line 1161, in heartbeat
    response = await retry_operation(
  File "/home/shankaras1/.venv/lib/python3.10/site-packages/distributed/utils_comm.py", line 383, in retry_operation
    return await retry(
  File "/home/shankaras1/.venv/lib/python3.10/site-packages/distributed/utils_comm.py", line 368, in retry
    return await coro()
  File "/home/shankaras1/.venv/lib/python3.10/site-packages/distributed/core.py", line 1150, in send_recv_from_rpc
    comm = await self.pool.connect(self.addr)
  File "/home/shankaras1/.venv/lib/python3.10/site-packages/distributed/core.py", line 1371, in connect
    return await connect_attempt
  File "/home/shankaras1/.venv/lib/python3.10/site-packages/distributed/core.py", line 1307, in _connect
    comm = await connect(
  File "/home/shankaras1/.venv/lib/python3.10/site-packages/distributed/comm/core.py", line 333, in connect
    raise OSError(
OSError: Timed out during handshake while connecting to tcp://127.0.0.1:39719 after 30 s
2024-05-09 22:08:10,707 - distributed.worker - ERROR - Timed out during handshake while connecting to tcp://127.0.0.1:39719 after 30 s
Traceback (most recent call last):
  File "/home/shankaras1/.venv/lib/python3.10/site-packages/distributed/comm/tcp.py", line 264, in write
    async def write(self, msg, serializers=None, on_error="message"):
asyncio.exceptions.CancelledError

During handling of the above exception, another exception occurred:

Traceback (most recent call last):
  File "/easybuild/software/Python/3.10.8-GCCcore-12.2.0/lib/python3.10/asyncio/tasks.py", line 418, in wait_for
    return fut.result()
asyncio.exceptions.CancelledError

The above exception was the direct cause of the following exception:

Traceback (most recent call last):
  File "/home/shankaras1/.venv/lib/python3.10/site-packages/distributed/comm/core.py", line 329, in connect
    await asyncio.wait_for(comm.write(local_info), time_left())
  File "/easybuild/software/Python/3.10.8-GCCcore-12.2.0/lib/python3.10/asyncio/tasks.py", line 420, in wait_for
    raise exceptions.TimeoutError() from exc
asyncio.exceptions.TimeoutError

The above exception was the direct cause of the following exception:

Traceback (most recent call last):
  File "/home/shankaras1/.venv/lib/python3.10/site-packages/distributed/worker.py", line 1161, in heartbeat
    response = await retry_operation(
  File "/home/shankaras1/.venv/lib/python3.10/site-packages/distributed/utils_comm.py", line 383, in retry_operation
    return await retry(
  File "/home/shankaras1/.venv/lib/python3.10/site-packages/distributed/utils_comm.py", line 368, in retry
    return await coro()
  File "/home/shankaras1/.venv/lib/python3.10/site-packages/distributed/core.py", line 1150, in send_recv_from_rpc
    comm = await self.pool.connect(self.addr)
  File "/home/shankaras1/.venv/lib/python3.10/site-packages/distributed/core.py", line 1371, in connect
    return await connect_attempt
  File "/home/shankaras1/.venv/lib/python3.10/site-packages/distributed/core.py", line 1307, in _connect
    comm = await connect(
  File "/home/shankaras1/.venv/lib/python3.10/site-packages/distributed/comm/core.py", line 333, in connect
    raise OSError(
OSError: Timed out during handshake while connecting to tcp://127.0.0.1:39719 after 30 s
2024-05-09 22:08:26,365 - tornado.application - ERROR - Exception in callback functools.partial(<bound method IOLoop._discard_future_result of <tornado.platform.asyncio.AsyncIOLoop object at 0x155548c28b20>>, <Task finished name='Task-16' coro=<Worker.heartbeat() done, defined at /home/shankaras1/.venv/lib/python3.10/site-packages/distributed/worker.py:1153> exception=OSError('Timed out during handshake while connecting to tcp://127.0.0.1:39719 after 30 s')>)
Traceback (most recent call last):
  File "/home/shankaras1/.venv/lib/python3.10/site-packages/distributed/comm/tcp.py", line 264, in write
    async def write(self, msg, serializers=None, on_error="message"):
asyncio.exceptions.CancelledError

During handling of the above exception, another exception occurred:

Traceback (most recent call last):
  File "/easybuild/software/Python/3.10.8-GCCcore-12.2.0/lib/python3.10/asyncio/tasks.py", line 418, in wait_for
    return fut.result()
asyncio.exceptions.CancelledError

The above exception was the direct cause of the following exception:

Traceback (most recent call last):
  File "/home/shankaras1/.venv/lib/python3.10/site-packages/distributed/comm/core.py", line 329, in connect
    await asyncio.wait_for(comm.write(local_info), time_left())
  File "/easybuild/software/Python/3.10.8-GCCcore-12.2.0/lib/python3.10/asyncio/tasks.py", line 420, in wait_for
    raise exceptions.TimeoutError() from exc
asyncio.exceptions.TimeoutError

The above exception was the direct cause of the following exception:

Traceback (most recent call last):
  File "/home/shankaras1/.venv/lib/python3.10/site-packages/tornado/ioloop.py", line 741, in _run_callback
    ret = callback()
  File "/home/shankaras1/.venv/lib/python3.10/site-packages/tornado/ioloop.py", line 765, in _discard_future_result
    future.result()
  File "/home/shankaras1/.venv/lib/python3.10/site-packages/distributed/worker.py", line 1207, in heartbeat
    raise e
  File "/home/shankaras1/.venv/lib/python3.10/site-packages/distributed/worker.py", line 1161, in heartbeat
    response = await retry_operation(
  File "/home/shankaras1/.venv/lib/python3.10/site-packages/distributed/utils_comm.py", line 383, in retry_operation
    return await retry(
  File "/home/shankaras1/.venv/lib/python3.10/site-packages/distributed/utils_comm.py", line 368, in retry
    return await coro()
  File "/home/shankaras1/.venv/lib/python3.10/site-packages/distributed/core.py", line 1150, in send_recv_from_rpc
    comm = await self.pool.connect(self.addr)
  File "/home/shankaras1/.venv/lib/python3.10/site-packages/distributed/core.py", line 1371, in connect
    return await connect_attempt
  File "/home/shankaras1/.venv/lib/python3.10/site-packages/distributed/core.py", line 1307, in _connect
    comm = await connect(
  File "/home/shankaras1/.venv/lib/python3.10/site-packages/distributed/comm/core.py", line 333, in connect
    raise OSError(
OSError: Timed out during handshake while connecting to tcp://127.0.0.1:39719 after 30 s
2024-05-09 22:08:27,354 - tornado.application - ERROR - Exception in callback functools.partial(<bound method IOLoop._discard_future_result of <tornado.platform.asyncio.AsyncIOLoop object at 0x155548c28b20>>, <Task finished name='Task-16' coro=<Worker.heartbeat() done, defined at /home/shankaras1/.venv/lib/python3.10/site-packages/distributed/worker.py:1153> exception=OSError('Timed out during handshake while connecting to tcp://127.0.0.1:39719 after 30 s')>)
Traceback (most recent call last):
  File "/home/shankaras1/.venv/lib/python3.10/site-packages/distributed/comm/tcp.py", line 264, in write
    async def write(self, msg, serializers=None, on_error="message"):
asyncio.exceptions.CancelledError

During handling of the above exception, another exception occurred:

Traceback (most recent call last):
  File "/easybuild/software/Python/3.10.8-GCCcore-12.2.0/lib/python3.10/asyncio/tasks.py", line 418, in wait_for
    return fut.result()
asyncio.exceptions.CancelledError

The above exception was the direct cause of the following exception:

Traceback (most recent call last):
  File "/home/shankaras1/.venv/lib/python3.10/site-packages/distributed/comm/core.py", line 329, in connect
    await asyncio.wait_for(comm.write(local_info), time_left())
  File "/easybuild/software/Python/3.10.8-GCCcore-12.2.0/lib/python3.10/asyncio/tasks.py", line 420, in wait_for
    raise exceptions.TimeoutError() from exc
asyncio.exceptions.TimeoutError

The above exception was the direct cause of the following exception:

Traceback (most recent call last):
  File "/home/shankaras1/.venv/lib/python3.10/site-packages/tornado/ioloop.py", line 741, in _run_callback
    ret = callback()
  File "/home/shankaras1/.venv/lib/python3.10/site-packages/tornado/ioloop.py", line 765, in _discard_future_result
    future.result()
  File "/home/shankaras1/.venv/lib/python3.10/site-packages/distributed/worker.py", line 1207, in heartbeat
    raise e
  File "/home/shankaras1/.venv/lib/python3.10/site-packages/distributed/worker.py", line 1161, in heartbeat
    response = await retry_operation(
  File "/home/shankaras1/.venv/lib/python3.10/site-packages/distributed/utils_comm.py", line 383, in retry_operation
    return await retry(
  File "/home/shankaras1/.venv/lib/python3.10/site-packages/distributed/utils_comm.py", line 368, in retry
    return await coro()
  File "/home/shankaras1/.venv/lib/python3.10/site-packages/distributed/core.py", line 1150, in send_recv_from_rpc
    comm = await self.pool.connect(self.addr)
  File "/home/shankaras1/.venv/lib/python3.10/site-packages/distributed/core.py", line 1371, in connect
    return await connect_attempt
  File "/home/shankaras1/.venv/lib/python3.10/site-packages/distributed/core.py", line 1307, in _connect
    comm = await connect(
  File "/home/shankaras1/.venv/lib/python3.10/site-packages/distributed/comm/core.py", line 333, in connect
    raise OSError(
OSError: Timed out during handshake while connecting to tcp://127.0.0.1:39719 after 30 s
2024-05-09 22:08:21,140 - tornado.application - ERROR - Exception in callback functools.partial(<bound method IOLoop._discard_future_result of <tornado.platform.asyncio.AsyncIOLoop object at 0x155548c28b20>>, <Task finished name='Task-16' coro=<Worker.heartbeat() done, defined at /home/shankaras1/.venv/lib/python3.10/site-packages/distributed/worker.py:1153> exception=OSError('Timed out during handshake while connecting to tcp://127.0.0.1:39719 after 30 s')>)
Traceback (most recent call last):
  File "/home/shankaras1/.venv/lib/python3.10/site-packages/distributed/comm/tcp.py", line 264, in write
    async def write(self, msg, serializers=None, on_error="message"):
asyncio.exceptions.CancelledError

During handling of the above exception, another exception occurred:

Traceback (most recent call last):
  File "/easybuild/software/Python/3.10.8-GCCcore-12.2.0/lib/python3.10/asyncio/tasks.py", line 418, in wait_for
    return fut.result()
asyncio.exceptions.CancelledError

The above exception was the direct cause of the following exception:

Traceback (most recent call last):
  File "/home/shankaras1/.venv/lib/python3.10/site-packages/distributed/comm/core.py", line 329, in connect
    await asyncio.wait_for(comm.write(local_info), time_left())
  File "/easybuild/software/Python/3.10.8-GCCcore-12.2.0/lib/python3.10/asyncio/tasks.py", line 420, in wait_for
    raise exceptions.TimeoutError() from exc
asyncio.exceptions.TimeoutError

The above exception was the direct cause of the following exception:

Traceback (most recent call last):
  File "/home/shankaras1/.venv/lib/python3.10/site-packages/tornado/ioloop.py", line 741, in _run_callback
    ret = callback()
  File "/home/shankaras1/.venv/lib/python3.10/site-packages/tornado/ioloop.py", line 765, in _discard_future_result
    future.result()
  File "/home/shankaras1/.venv/lib/python3.10/site-packages/distributed/worker.py", line 1207, in heartbeat
    raise e
  File "/home/shankaras1/.venv/lib/python3.10/site-packages/distributed/worker.py", line 1161, in heartbeat
    response = await retry_operation(
  File "/home/shankaras1/.venv/lib/python3.10/site-packages/distributed/utils_comm.py", line 383, in retry_operation
    return await retry(
  File "/home/shankaras1/.venv/lib/python3.10/site-packages/distributed/utils_comm.py", line 368, in retry
    return await coro()
  File "/home/shankaras1/.venv/lib/python3.10/site-packages/distributed/core.py", line 1150, in send_recv_from_rpc
    comm = await self.pool.connect(self.addr)
  File "/home/shankaras1/.venv/lib/python3.10/site-packages/distributed/core.py", line 1371, in connect
    return await connect_attempt
  File "/home/shankaras1/.venv/lib/python3.10/site-packages/distributed/core.py", line 1307, in _connect
    comm = await connect(
  File "/home/shankaras1/.venv/lib/python3.10/site-packages/distributed/comm/core.py", line 333, in connect
    raise OSError(
OSError: Timed out during handshake while connecting to tcp://127.0.0.1:39719 after 30 s
2024-05-09 22:08:27,168 - tornado.application - ERROR - Exception in callback functools.partial(<bound method IOLoop._discard_future_result of <tornado.platform.asyncio.AsyncIOLoop object at 0x155548c28b20>>, <Task finished name='Task-16' coro=<Worker.heartbeat() done, defined at /home/shankaras1/.venv/lib/python3.10/site-packages/distributed/worker.py:1153> exception=OSError('Timed out during handshake while connecting to tcp://127.0.0.1:39719 after 30 s')>)
Traceback (most recent call last):
  File "/home/shankaras1/.venv/lib/python3.10/site-packages/distributed/comm/tcp.py", line 264, in write
    async def write(self, msg, serializers=None, on_error="message"):
asyncio.exceptions.CancelledError

During handling of the above exception, another exception occurred:

Traceback (most recent call last):
  File "/easybuild/software/Python/3.10.8-GCCcore-12.2.0/lib/python3.10/asyncio/tasks.py", line 418, in wait_for
    return fut.result()
asyncio.exceptions.CancelledError

The above exception was the direct cause of the following exception:

Traceback (most recent call last):
  File "/home/shankaras1/.venv/lib/python3.10/site-packages/distributed/comm/core.py", line 329, in connect
    await asyncio.wait_for(comm.write(local_info), time_left())
  File "/easybuild/software/Python/3.10.8-GCCcore-12.2.0/lib/python3.10/asyncio/tasks.py", line 420, in wait_for
    raise exceptions.TimeoutError() from exc
asyncio.exceptions.TimeoutError

The above exception was the direct cause of the following exception:

Traceback (most recent call last):
  File "/home/shankaras1/.venv/lib/python3.10/site-packages/tornado/ioloop.py", line 741, in _run_callback
    ret = callback()
  File "/home/shankaras1/.venv/lib/python3.10/site-packages/tornado/ioloop.py", line 765, in _discard_future_result
    future.result()
  File "/home/shankaras1/.venv/lib/python3.10/site-packages/distributed/worker.py", line 1207, in heartbeat
    raise e
  File "/home/shankaras1/.venv/lib/python3.10/site-packages/distributed/worker.py", line 1161, in heartbeat
    response = await retry_operation(
  File "/home/shankaras1/.venv/lib/python3.10/site-packages/distributed/utils_comm.py", line 383, in retry_operation
    return await retry(
  File "/home/shankaras1/.venv/lib/python3.10/site-packages/distributed/utils_comm.py", line 368, in retry
    return await coro()
  File "/home/shankaras1/.venv/lib/python3.10/site-packages/distributed/core.py", line 1150, in send_recv_from_rpc
    comm = await self.pool.connect(self.addr)
  File "/home/shankaras1/.venv/lib/python3.10/site-packages/distributed/core.py", line 1371, in connect
    return await connect_attempt
  File "/home/shankaras1/.venv/lib/python3.10/site-packages/distributed/core.py", line 1307, in _connect
    comm = await connect(
  File "/home/shankaras1/.venv/lib/python3.10/site-packages/distributed/comm/core.py", line 333, in connect
    raise OSError(
OSError: Timed out during handshake while connecting to tcp://127.0.0.1:39719 after 30 s
2024-05-09 22:08:17,544 - tornado.application - ERROR - Exception in callback functools.partial(<bound method IOLoop._discard_future_result of <tornado.platform.asyncio.AsyncIOLoop object at 0x155548c28b20>>, <Task finished name='Task-16' coro=<Worker.heartbeat() done, defined at /home/shankaras1/.venv/lib/python3.10/site-packages/distributed/worker.py:1153> exception=OSError('Timed out during handshake while connecting to tcp://127.0.0.1:39719 after 30 s')>)
Traceback (most recent call last):
  File "/home/shankaras1/.venv/lib/python3.10/site-packages/distributed/comm/tcp.py", line 264, in write
    async def write(self, msg, serializers=None, on_error="message"):
asyncio.exceptions.CancelledError

During handling of the above exception, another exception occurred:

Traceback (most recent call last):
  File "/easybuild/software/Python/3.10.8-GCCcore-12.2.0/lib/python3.10/asyncio/tasks.py", line 418, in wait_for
    return fut.result()
asyncio.exceptions.CancelledError

The above exception was the direct cause of the following exception:

Traceback (most recent call last):
  File "/home/shankaras1/.venv/lib/python3.10/site-packages/distributed/comm/core.py", line 329, in connect
    await asyncio.wait_for(comm.write(local_info), time_left())
  File "/easybuild/software/Python/3.10.8-GCCcore-12.2.0/lib/python3.10/asyncio/tasks.py", line 420, in wait_for
    raise exceptions.TimeoutError() from exc
asyncio.exceptions.TimeoutError

The above exception was the direct cause of the following exception:

Traceback (most recent call last):
  File "/home/shankaras1/.venv/lib/python3.10/site-packages/tornado/ioloop.py", line 741, in _run_callback
    ret = callback()
  File "/home/shankaras1/.venv/lib/python3.10/site-packages/tornado/ioloop.py", line 765, in _discard_future_result
    future.result()
  File "/home/shankaras1/.venv/lib/python3.10/site-packages/distributed/worker.py", line 1207, in heartbeat
    raise e
  File "/home/shankaras1/.venv/lib/python3.10/site-packages/distributed/worker.py", line 1161, in heartbeat
    response = await retry_operation(
  File "/home/shankaras1/.venv/lib/python3.10/site-packages/distributed/utils_comm.py", line 383, in retry_operation
    return await retry(
  File "/home/shankaras1/.venv/lib/python3.10/site-packages/distributed/utils_comm.py", line 368, in retry
    return await coro()
  File "/home/shankaras1/.venv/lib/python3.10/site-packages/distributed/core.py", line 1150, in send_recv_from_rpc
    comm = await self.pool.connect(self.addr)
  File "/home/shankaras1/.venv/lib/python3.10/site-packages/distributed/core.py", line 1371, in connect
    return await connect_attempt
  File "/home/shankaras1/.venv/lib/python3.10/site-packages/distributed/core.py", line 1307, in _connect
    comm = await connect(
  File "/home/shankaras1/.venv/lib/python3.10/site-packages/distributed/comm/core.py", line 333, in connect
    raise OSError(
OSError: Timed out during handshake while connecting to tcp://127.0.0.1:39719 after 30 s
omega = 0.00566567 finished in 33.83688280498609 seconds.
omega = 0.0179233 finished in 34.10045715601882 seconds.
omega = 0.00569183 entered
omega = 0.0180061 entered
omega = 0.179371 finished in 34.22005906497361 seconds.
omega = 0.00100693 finished in 34.25674322299892 seconds.
omega = 0.180199 entered
omega = 0.00101158 entered
omega = 0.00179095 finished in 34.499651263002306 seconds.
omega = 0.00179922 entered
omega = 0.00318543 finished in 34.55997797200689 seconds.
omega = 0.00320014 entered
omega = 0.0318787 finished in 34.66851284497534 seconds.
omega = 0.0320259 entered
omega = 0.100848 finished in 34.41698574999464 seconds.
omega = 0.101314 entered
omega = 0.0567002 finished in 34.97133750098874 seconds.
omega = 0.056962 entered
omega = 0.319032 finished in 35.44568053999683 seconds.
omega = 0.320505 entered
omega = 0.0100771 finished in 35.35213565299637 seconds.
omega = 0.0101236 entered
/data1/shankaras1/python_files/BLG/v3_RGF_BBG.py:235: IntegrationWarning: The integral is probably divergent, or slowly convergent.
  intlist = [quad(call_int,window[0],window[1],limit=200,epsabs=delta)[0] for window in ranges]
omega = 0.567437 finished in 38.34567078598775 seconds.
omega = 0.570057 entered
omega = 1.78683e-06 finished in 39.01767304900568 seconds.
omega = 1.79508e-06 entered
omega = 3.1781e-06 finished in 40.106564172019716 seconds.
omega = 3.19277e-06 entered
omega = 5.65697e-05 finished in 40.25985548002063 seconds.
omega = 5.68309e-05 entered
omega = 5.65263e-06 finished in 39.748086531995796 seconds.
omega = 5.67873e-06 entered
omega = 1.00539e-05 finished in 40.53806659497786 seconds.
omega = 1.01003e-05 entered
omega = 0.000100616 finished in 41.13515776497661 seconds.
omega = 0.000101081 entered
omega = 1.78821e-05 finished in 41.22003663898795 seconds.
omega = 1.79646e-05 entered
omega = 0.000318298 finished in 40.51884720599628 seconds.
omega = 0.000319768 entered
omega = 1.00462e-06 finished in 43.45403454298503 seconds.
omega = 1.00926e-06 entered
omega = 0.000178958 finished in 42.7521459540003 seconds.
omega = 0.000179784 entered
omega = 3.18054e-05 finished in 42.801104149984894 seconds.
omega = 3.19523e-05 entered
omega = 0.000566132 finished in 42.86569528101245 seconds.
omega = 0.000568746 entered
omega = 0.0180061 finished in 33.85963907901896 seconds.
omega = 0.0180892 entered
omega = 0.00569183 finished in 33.92403709801147 seconds.
2024-05-09 22:09:12,357 - distributed.worker - ERROR - Timed out during handshake while connecting to tcp://127.0.0.1:39719 after 30 s
Traceback (most recent call last):
  File "/home/shankaras1/.venv/lib/python3.10/site-packages/distributed/comm/tcp.py", line 264, in write
    async def write(self, msg, serializers=None, on_error="message"):
asyncio.exceptions.CancelledError

During handling of the above exception, another exception occurred:

Traceback (most recent call last):
  File "/easybuild/software/Python/3.10.8-GCCcore-12.2.0/lib/python3.10/asyncio/tasks.py", line 418, in wait_for
    return fut.result()
asyncio.exceptions.CancelledError

The above exception was the direct cause of the following exception:

Traceback (most recent call last):
  File "/home/shankaras1/.venv/lib/python3.10/site-packages/distributed/comm/core.py", line 329, in connect
    await asyncio.wait_for(comm.write(local_info), time_left())
  File "/easybuild/software/Python/3.10.8-GCCcore-12.2.0/lib/python3.10/asyncio/tasks.py", line 420, in wait_for
    raise exceptions.TimeoutError() from exc
asyncio.exceptions.TimeoutError

The above exception was the direct cause of the following exception:

Traceback (most recent call last):
  File "/home/shankaras1/.venv/lib/python3.10/site-packages/distributed/worker.py", line 1161, in heartbeat
    response = await retry_operation(
  File "/home/shankaras1/.venv/lib/python3.10/site-packages/distributed/utils_comm.py", line 383, in retry_operation
    return await retry(
  File "/home/shankaras1/.venv/lib/python3.10/site-packages/distributed/utils_comm.py", line 368, in retry
    return await coro()
  File "/home/shankaras1/.venv/lib/python3.10/site-packages/distributed/core.py", line 1150, in send_recv_from_rpc
    comm = await self.pool.connect(self.addr)
  File "/home/shankaras1/.venv/lib/python3.10/site-packages/distributed/core.py", line 1371, in connect
    return await connect_attempt
  File "/home/shankaras1/.venv/lib/python3.10/site-packages/distributed/core.py", line 1307, in _connect
    comm = await connect(
  File "/home/shankaras1/.venv/lib/python3.10/site-packages/distributed/comm/core.py", line 333, in connect
    raise OSError(
OSError: Timed out during handshake while connecting to tcp://127.0.0.1:39719 after 30 s
2024-05-09 22:09:12,359 - tornado.application - ERROR - Exception in callback functools.partial(<bound method IOLoop._discard_future_result of <tornado.platform.asyncio.AsyncIOLoop object at 0x155548c28b20>>, <Task finished name='Task-32' coro=<Worker.heartbeat() done, defined at /home/shankaras1/.venv/lib/python3.10/site-packages/distributed/worker.py:1153> exception=OSError('Timed out during handshake while connecting to tcp://127.0.0.1:39719 after 30 s')>)
Traceback (most recent call last):
  File "/home/shankaras1/.venv/lib/python3.10/site-packages/distributed/comm/tcp.py", line 264, in write
    async def write(self, msg, serializers=None, on_error="message"):
asyncio.exceptions.CancelledError

During handling of the above exception, another exception occurred:

Traceback (most recent call last):
  File "/easybuild/software/Python/3.10.8-GCCcore-12.2.0/lib/python3.10/asyncio/tasks.py", line 418, in wait_for
    return fut.result()
asyncio.exceptions.CancelledError

The above exception was the direct cause of the following exception:

Traceback (most recent call last):
  File "/home/shankaras1/.venv/lib/python3.10/site-packages/distributed/comm/core.py", line 329, in connect
    await asyncio.wait_for(comm.write(local_info), time_left())
  File "/easybuild/software/Python/3.10.8-GCCcore-12.2.0/lib/python3.10/asyncio/tasks.py", line 420, in wait_for
    raise exceptions.TimeoutError() from exc
asyncio.exceptions.TimeoutError

The above exception was the direct cause of the following exception:

Traceback (most recent call last):
  File "/home/shankaras1/.venv/lib/python3.10/site-packages/tornado/ioloop.py", line 741, in _run_callback
    ret = callback()
  File "/home/shankaras1/.venv/lib/python3.10/site-packages/tornado/ioloop.py", line 765, in _discard_future_result
    future.result()
  File "/home/shankaras1/.venv/lib/python3.10/site-packages/distributed/worker.py", line 1207, in heartbeat
    raise e
  File "/home/shankaras1/.venv/lib/python3.10/site-packages/distributed/worker.py", line 1161, in heartbeat
    response = await retry_operation(
  File "/home/shankaras1/.venv/lib/python3.10/site-packages/distributed/utils_comm.py", line 383, in retry_operation
    return await retry(
  File "/home/shankaras1/.venv/lib/python3.10/site-packages/distributed/utils_comm.py", line 368, in retry
    return await coro()
  File "/home/shankaras1/.venv/lib/python3.10/site-packages/distributed/core.py", line 1150, in send_recv_from_rpc
    comm = await self.pool.connect(self.addr)
  File "/home/shankaras1/.venv/lib/python3.10/site-packages/distributed/core.py", line 1371, in connect
    return await connect_attempt
  File "/home/shankaras1/.venv/lib/python3.10/site-packages/distributed/core.py", line 1307, in _connect
    comm = await connect(
  File "/home/shankaras1/.venv/lib/python3.10/site-packages/distributed/comm/core.py", line 333, in connect
    raise OSError(
OSError: Timed out during handshake while connecting to tcp://127.0.0.1:39719 after 30 s
omega = 0.00571811 entered
omega = 0.180199 finished in 34.10788423800841 seconds.
omega = 0.181031 entered
omega = 0.00101158 finished in 34.235773648979375 seconds.
omega = 0.00101625 entered
2024-05-09 22:09:12,966 - distributed.worker - ERROR - Timed out during handshake while connecting to tcp://127.0.0.1:39719 after 30 s
Traceback (most recent call last):
  File "/home/shankaras1/.venv/lib/python3.10/site-packages/distributed/comm/tcp.py", line 264, in write
    async def write(self, msg, serializers=None, on_error="message"):
asyncio.exceptions.CancelledError

During handling of the above exception, another exception occurred:

Traceback (most recent call last):
  File "/easybuild/software/Python/3.10.8-GCCcore-12.2.0/lib/python3.10/asyncio/tasks.py", line 418, in wait_for
    return fut.result()
asyncio.exceptions.CancelledError

The above exception was the direct cause of the following exception:

Traceback (most recent call last):
  File "/home/shankaras1/.venv/lib/python3.10/site-packages/distributed/comm/core.py", line 329, in connect
    await asyncio.wait_for(comm.write(local_info), time_left())
  File "/easybuild/software/Python/3.10.8-GCCcore-12.2.0/lib/python3.10/asyncio/tasks.py", line 420, in wait_for
    raise exceptions.TimeoutError() from exc
asyncio.exceptions.TimeoutError

The above exception was the direct cause of the following exception:

Traceback (most recent call last):
  File "/home/shankaras1/.venv/lib/python3.10/site-packages/distributed/worker.py", line 1161, in heartbeat
    response = await retry_operation(
  File "/home/shankaras1/.venv/lib/python3.10/site-packages/distributed/utils_comm.py", line 383, in retry_operation
    return await retry(
  File "/home/shankaras1/.venv/lib/python3.10/site-packages/distributed/utils_comm.py", line 368, in retry
    return await coro()
  File "/home/shankaras1/.venv/lib/python3.10/site-packages/distributed/core.py", line 1150, in send_recv_from_rpc
    comm = await self.pool.connect(self.addr)
  File "/home/shankaras1/.venv/lib/python3.10/site-packages/distributed/core.py", line 1371, in connect
    return await connect_attempt
  File "/home/shankaras1/.venv/lib/python3.10/site-packages/distributed/core.py", line 1307, in _connect
    comm = await connect(
  File "/home/shankaras1/.venv/lib/python3.10/site-packages/distributed/comm/core.py", line 333, in connect
    raise OSError(
OSError: Timed out during handshake while connecting to tcp://127.0.0.1:39719 after 30 s
omega = 0.00179922 finished in 34.57268454300356 seconds.
omega = 0.00180753 entered
omega = 0.00320014 finished in 34.51375455601374 seconds.
omega = 0.00321491 entered
omega = 0.0320259 finished in 34.27614895501756 seconds.
omega = 0.0321738 entered
2024-05-09 22:09:12,298 - distributed.worker - ERROR - Timed out during handshake while connecting to tcp://127.0.0.1:39719 after 30 s
Traceback (most recent call last):
  File "/home/shankaras1/.venv/lib/python3.10/site-packages/distributed/comm/tcp.py", line 264, in write
    async def write(self, msg, serializers=None, on_error="message"):
asyncio.exceptions.CancelledError

During handling of the above exception, another exception occurred:

Traceback (most recent call last):
  File "/easybuild/software/Python/3.10.8-GCCcore-12.2.0/lib/python3.10/asyncio/tasks.py", line 418, in wait_for
    return fut.result()
asyncio.exceptions.CancelledError

The above exception was the direct cause of the following exception:

Traceback (most recent call last):
  File "/home/shankaras1/.venv/lib/python3.10/site-packages/distributed/comm/core.py", line 329, in connect
    await asyncio.wait_for(comm.write(local_info), time_left())
  File "/easybuild/software/Python/3.10.8-GCCcore-12.2.0/lib/python3.10/asyncio/tasks.py", line 420, in wait_for
    raise exceptions.TimeoutError() from exc
asyncio.exceptions.TimeoutError

The above exception was the direct cause of the following exception:

Traceback (most recent call last):
  File "/home/shankaras1/.venv/lib/python3.10/site-packages/distributed/worker.py", line 1161, in heartbeat
    response = await retry_operation(
  File "/home/shankaras1/.venv/lib/python3.10/site-packages/distributed/utils_comm.py", line 383, in retry_operation
    return await retry(
  File "/home/shankaras1/.venv/lib/python3.10/site-packages/distributed/utils_comm.py", line 368, in retry
    return await coro()
  File "/home/shankaras1/.venv/lib/python3.10/site-packages/distributed/core.py", line 1150, in send_recv_from_rpc
    comm = await self.pool.connect(self.addr)
  File "/home/shankaras1/.venv/lib/python3.10/site-packages/distributed/core.py", line 1371, in connect
    return await connect_attempt
  File "/home/shankaras1/.venv/lib/python3.10/site-packages/distributed/core.py", line 1307, in _connect
    comm = await connect(
  File "/home/shankaras1/.venv/lib/python3.10/site-packages/distributed/comm/core.py", line 333, in connect
    raise OSError(
OSError: Timed out during handshake while connecting to tcp://127.0.0.1:39719 after 30 s
2024-05-09 22:09:13,774 - distributed.worker - ERROR - Timed out during handshake while connecting to tcp://127.0.0.1:39719 after 30 s
Traceback (most recent call last):
  File "/home/shankaras1/.venv/lib/python3.10/site-packages/distributed/comm/tcp.py", line 214, in read
    async def read(self, deserializers=None):
asyncio.exceptions.CancelledError

During handling of the above exception, another exception occurred:

Traceback (most recent call last):
  File "/easybuild/software/Python/3.10.8-GCCcore-12.2.0/lib/python3.10/asyncio/tasks.py", line 418, in wait_for
    return fut.result()
asyncio.exceptions.CancelledError

The above exception was the direct cause of the following exception:

Traceback (most recent call last):
  File "/home/shankaras1/.venv/lib/python3.10/site-packages/distributed/comm/core.py", line 328, in connect
    handshake = await asyncio.wait_for(comm.read(), time_left())
  File "/easybuild/software/Python/3.10.8-GCCcore-12.2.0/lib/python3.10/asyncio/tasks.py", line 420, in wait_for
    raise exceptions.TimeoutError() from exc
asyncio.exceptions.TimeoutError

The above exception was the direct cause of the following exception:

Traceback (most recent call last):
  File "/home/shankaras1/.venv/lib/python3.10/site-packages/distributed/worker.py", line 1161, in heartbeat
    response = await retry_operation(
  File "/home/shankaras1/.venv/lib/python3.10/site-packages/distributed/utils_comm.py", line 383, in retry_operation
    return await retry(
  File "/home/shankaras1/.venv/lib/python3.10/site-packages/distributed/utils_comm.py", line 368, in retry
    return await coro()
  File "/home/shankaras1/.venv/lib/python3.10/site-packages/distributed/core.py", line 1150, in send_recv_from_rpc
    comm = await self.pool.connect(self.addr)
  File "/home/shankaras1/.venv/lib/python3.10/site-packages/distributed/core.py", line 1371, in connect
    return await connect_attempt
  File "/home/shankaras1/.venv/lib/python3.10/site-packages/distributed/core.py", line 1307, in _connect
    comm = await connect(
  File "/home/shankaras1/.venv/lib/python3.10/site-packages/distributed/comm/core.py", line 333, in connect
    raise OSError(
OSError: Timed out during handshake while connecting to tcp://127.0.0.1:39719 after 30 s
omega = 0.101314 finished in 34.8031112519966 seconds.
omega = 0.101782 entered
omega = 0.056962 finished in 34.58107209499576 seconds.
2024-05-09 22:09:14,894 - distributed.worker - ERROR - Timed out during handshake while connecting to tcp://127.0.0.1:39719 after 30 s
Traceback (most recent call last):
  File "/home/shankaras1/.venv/lib/python3.10/site-packages/distributed/comm/tcp.py", line 214, in read
    async def read(self, deserializers=None):
asyncio.exceptions.CancelledError

During handling of the above exception, another exception occurred:

Traceback (most recent call last):
  File "/easybuild/software/Python/3.10.8-GCCcore-12.2.0/lib/python3.10/asyncio/tasks.py", line 418, in wait_for
    return fut.result()
asyncio.exceptions.CancelledError

The above exception was the direct cause of the following exception:

Traceback (most recent call last):
  File "/home/shankaras1/.venv/lib/python3.10/site-packages/distributed/comm/core.py", line 328, in connect
    handshake = await asyncio.wait_for(comm.read(), time_left())
  File "/easybuild/software/Python/3.10.8-GCCcore-12.2.0/lib/python3.10/asyncio/tasks.py", line 420, in wait_for
    raise exceptions.TimeoutError() from exc
asyncio.exceptions.TimeoutError

The above exception was the direct cause of the following exception:

Traceback (most recent call last):
  File "/home/shankaras1/.venv/lib/python3.10/site-packages/distributed/worker.py", line 1161, in heartbeat
    response = await retry_operation(
  File "/home/shankaras1/.venv/lib/python3.10/site-packages/distributed/utils_comm.py", line 383, in retry_operation
    return await retry(
  File "/home/shankaras1/.venv/lib/python3.10/site-packages/distributed/utils_comm.py", line 368, in retry
    return await coro()
  File "/home/shankaras1/.venv/lib/python3.10/site-packages/distributed/core.py", line 1150, in send_recv_from_rpc
    comm = await self.pool.connect(self.addr)
  File "/home/shankaras1/.venv/lib/python3.10/site-packages/distributed/core.py", line 1371, in connect
    return await connect_attempt
  File "/home/shankaras1/.venv/lib/python3.10/site-packages/distributed/core.py", line 1307, in _connect
    comm = await connect(
  File "/home/shankaras1/.venv/lib/python3.10/site-packages/distributed/comm/core.py", line 333, in connect
    raise OSError(
OSError: Timed out during handshake while connecting to tcp://127.0.0.1:39719 after 30 s
omega = 0.057225 entered
2024-05-09 22:09:14,897 - tornado.application - ERROR - Exception in callback functools.partial(<bound method IOLoop._discard_future_result of <tornado.platform.asyncio.AsyncIOLoop object at 0x155548c28b20>>, <Task finished name='Task-33' coro=<Worker.heartbeat() done, defined at /home/shankaras1/.venv/lib/python3.10/site-packages/distributed/worker.py:1153> exception=OSError('Timed out during handshake while connecting to tcp://127.0.0.1:39719 after 30 s')>)
Traceback (most recent call last):
  File "/home/shankaras1/.venv/lib/python3.10/site-packages/distributed/comm/tcp.py", line 214, in read
    async def read(self, deserializers=None):
asyncio.exceptions.CancelledError

During handling of the above exception, another exception occurred:

Traceback (most recent call last):
  File "/easybuild/software/Python/3.10.8-GCCcore-12.2.0/lib/python3.10/asyncio/tasks.py", line 418, in wait_for
    return fut.result()
asyncio.exceptions.CancelledError

The above exception was the direct cause of the following exception:

Traceback (most recent call last):
  File "/home/shankaras1/.venv/lib/python3.10/site-packages/distributed/comm/core.py", line 328, in connect
    handshake = await asyncio.wait_for(comm.read(), time_left())
  File "/easybuild/software/Python/3.10.8-GCCcore-12.2.0/lib/python3.10/asyncio/tasks.py", line 420, in wait_for
    raise exceptions.TimeoutError() from exc
asyncio.exceptions.TimeoutError

The above exception was the direct cause of the following exception:

Traceback (most recent call last):
  File "/home/shankaras1/.venv/lib/python3.10/site-packages/tornado/ioloop.py", line 741, in _run_callback
    ret = callback()
  File "/home/shankaras1/.venv/lib/python3.10/site-packages/tornado/ioloop.py", line 765, in _discard_future_result
    future.result()
  File "/home/shankaras1/.venv/lib/python3.10/site-packages/distributed/worker.py", line 1207, in heartbeat
    raise e
  File "/home/shankaras1/.venv/lib/python3.10/site-packages/distributed/worker.py", line 1161, in heartbeat
    response = await retry_operation(
  File "/home/shankaras1/.venv/lib/python3.10/site-packages/distributed/utils_comm.py", line 383, in retry_operation
    return await retry(
  File "/home/shankaras1/.venv/lib/python3.10/site-packages/distributed/utils_comm.py", line 368, in retry
    return await coro()
  File "/home/shankaras1/.venv/lib/python3.10/site-packages/distributed/core.py", line 1150, in send_recv_from_rpc
    comm = await self.pool.connect(self.addr)
  File "/home/shankaras1/.venv/lib/python3.10/site-packages/distributed/core.py", line 1371, in connect
    return await connect_attempt
  File "/home/shankaras1/.venv/lib/python3.10/site-packages/distributed/core.py", line 1307, in _connect
    comm = await connect(
  File "/home/shankaras1/.venv/lib/python3.10/site-packages/distributed/comm/core.py", line 333, in connect
    raise OSError(
OSError: Timed out during handshake while connecting to tcp://127.0.0.1:39719 after 30 s
omega = 0.320505 finished in 35.17315319701447 seconds.
omega = 0.321985 entered
2024-05-09 22:09:13,167 - tornado.application - ERROR - Exception in callback functools.partial(<bound method IOLoop._discard_future_result of <tornado.platform.asyncio.AsyncIOLoop object at 0x155548c28b20>>, <Task finished name='Task-32' coro=<Worker.heartbeat() done, defined at /home/shankaras1/.venv/lib/python3.10/site-packages/distributed/worker.py:1153> exception=OSError('Timed out during handshake while connecting to tcp://127.0.0.1:39719 after 30 s')>)
Traceback (most recent call last):
  File "/home/shankaras1/.venv/lib/python3.10/site-packages/distributed/comm/tcp.py", line 264, in write
    async def write(self, msg, serializers=None, on_error="message"):
asyncio.exceptions.CancelledError

During handling of the above exception, another exception occurred:

Traceback (most recent call last):
  File "/easybuild/software/Python/3.10.8-GCCcore-12.2.0/lib/python3.10/asyncio/tasks.py", line 418, in wait_for
    return fut.result()
asyncio.exceptions.CancelledError

The above exception was the direct cause of the following exception:

Traceback (most recent call last):
  File "/home/shankaras1/.venv/lib/python3.10/site-packages/distributed/comm/core.py", line 329, in connect
    await asyncio.wait_for(comm.write(local_info), time_left())
  File "/easybuild/software/Python/3.10.8-GCCcore-12.2.0/lib/python3.10/asyncio/tasks.py", line 420, in wait_for
    raise exceptions.TimeoutError() from exc
asyncio.exceptions.TimeoutError

The above exception was the direct cause of the following exception:

Traceback (most recent call last):
  File "/home/shankaras1/.venv/lib/python3.10/site-packages/tornado/ioloop.py", line 741, in _run_callback
    ret = callback()
  File "/home/shankaras1/.venv/lib/python3.10/site-packages/tornado/ioloop.py", line 765, in _discard_future_result
    future.result()
  File "/home/shankaras1/.venv/lib/python3.10/site-packages/distributed/worker.py", line 1207, in heartbeat
    raise e
  File "/home/shankaras1/.venv/lib/python3.10/site-packages/distributed/worker.py", line 1161, in heartbeat
    response = await retry_operation(
  File "/home/shankaras1/.venv/lib/python3.10/site-packages/distributed/utils_comm.py", line 383, in retry_operation
    return await retry(
  File "/home/shankaras1/.venv/lib/python3.10/site-packages/distributed/utils_comm.py", line 368, in retry
    return await coro()
  File "/home/shankaras1/.venv/lib/python3.10/site-packages/distributed/core.py", line 1150, in send_recv_from_rpc
    comm = await self.pool.connect(self.addr)
  File "/home/shankaras1/.venv/lib/python3.10/site-packages/distributed/core.py", line 1371, in connect
    return await connect_attempt
  File "/home/shankaras1/.venv/lib/python3.10/site-packages/distributed/core.py", line 1307, in _connect
    comm = await connect(
  File "/home/shankaras1/.venv/lib/python3.10/site-packages/distributed/comm/core.py", line 333, in connect
    raise OSError(
OSError: Timed out during handshake while connecting to tcp://127.0.0.1:39719 after 30 s
omega = 0.0101236 finished in 33.800051901023835 seconds.
omega = 0.0101703 entered
2024-05-09 22:09:14,281 - tornado.application - ERROR - Exception in callback functools.partial(<bound method IOLoop._discard_future_result of <tornado.platform.asyncio.AsyncIOLoop object at 0x155548c28b20>>, <Task finished name='Task-33' coro=<Worker.heartbeat() done, defined at /home/shankaras1/.venv/lib/python3.10/site-packages/distributed/worker.py:1153> exception=OSError('Timed out during handshake while connecting to tcp://127.0.0.1:39719 after 30 s')>)
Traceback (most recent call last):
  File "/home/shankaras1/.venv/lib/python3.10/site-packages/distributed/comm/tcp.py", line 264, in write
    async def write(self, msg, serializers=None, on_error="message"):
asyncio.exceptions.CancelledError

During handling of the above exception, another exception occurred:

Traceback (most recent call last):
  File "/easybuild/software/Python/3.10.8-GCCcore-12.2.0/lib/python3.10/asyncio/tasks.py", line 418, in wait_for
    return fut.result()
asyncio.exceptions.CancelledError

The above exception was the direct cause of the following exception:

Traceback (most recent call last):
  File "/home/shankaras1/.venv/lib/python3.10/site-packages/distributed/comm/core.py", line 329, in connect
    await asyncio.wait_for(comm.write(local_info), time_left())
  File "/easybuild/software/Python/3.10.8-GCCcore-12.2.0/lib/python3.10/asyncio/tasks.py", line 420, in wait_for
    raise exceptions.TimeoutError() from exc
asyncio.exceptions.TimeoutError

The above exception was the direct cause of the following exception:

Traceback (most recent call last):
  File "/home/shankaras1/.venv/lib/python3.10/site-packages/tornado/ioloop.py", line 741, in _run_callback
    ret = callback()
  File "/home/shankaras1/.venv/lib/python3.10/site-packages/tornado/ioloop.py", line 765, in _discard_future_result
    future.result()
  File "/home/shankaras1/.venv/lib/python3.10/site-packages/distributed/worker.py", line 1207, in heartbeat
    raise e
  File "/home/shankaras1/.venv/lib/python3.10/site-packages/distributed/worker.py", line 1161, in heartbeat
    response = await retry_operation(
  File "/home/shankaras1/.venv/lib/python3.10/site-packages/distributed/utils_comm.py", line 383, in retry_operation
    return await retry(
  File "/home/shankaras1/.venv/lib/python3.10/site-packages/distributed/utils_comm.py", line 368, in retry
    return await coro()
  File "/home/shankaras1/.venv/lib/python3.10/site-packages/distributed/core.py", line 1150, in send_recv_from_rpc
    comm = await self.pool.connect(self.addr)
  File "/home/shankaras1/.venv/lib/python3.10/site-packages/distributed/core.py", line 1371, in connect
    return await connect_attempt
  File "/home/shankaras1/.venv/lib/python3.10/site-packages/distributed/core.py", line 1307, in _connect
    comm = await connect(
  File "/home/shankaras1/.venv/lib/python3.10/site-packages/distributed/comm/core.py", line 333, in connect
    raise OSError(
OSError: Timed out during handshake while connecting to tcp://127.0.0.1:39719 after 30 s
omega = 0.570057 finished in 38.17018724497757 seconds.
omega = 0.57269 entered
2024-05-09 22:09:15,472 - tornado.application - ERROR - Exception in callback functools.partial(<bound method IOLoop._discard_future_result of <tornado.platform.asyncio.AsyncIOLoop object at 0x155548c28b20>>, <Task finished name='Task-33' coro=<Worker.heartbeat() done, defined at /home/shankaras1/.venv/lib/python3.10/site-packages/distributed/worker.py:1153> exception=OSError('Timed out during handshake while connecting to tcp://127.0.0.1:39719 after 30 s')>)
Traceback (most recent call last):
  File "/home/shankaras1/.venv/lib/python3.10/site-packages/distributed/comm/tcp.py", line 214, in read
    async def read(self, deserializers=None):
asyncio.exceptions.CancelledError

During handling of the above exception, another exception occurred:

Traceback (most recent call last):
  File "/easybuild/software/Python/3.10.8-GCCcore-12.2.0/lib/python3.10/asyncio/tasks.py", line 418, in wait_for
    return fut.result()
asyncio.exceptions.CancelledError

The above exception was the direct cause of the following exception:

Traceback (most recent call last):
  File "/home/shankaras1/.venv/lib/python3.10/site-packages/distributed/comm/core.py", line 328, in connect
    handshake = await asyncio.wait_for(comm.read(), time_left())
  File "/easybuild/software/Python/3.10.8-GCCcore-12.2.0/lib/python3.10/asyncio/tasks.py", line 420, in wait_for
    raise exceptions.TimeoutError() from exc
asyncio.exceptions.TimeoutError

The above exception was the direct cause of the following exception:

Traceback (most recent call last):
  File "/home/shankaras1/.venv/lib/python3.10/site-packages/tornado/ioloop.py", line 741, in _run_callback
    ret = callback()
  File "/home/shankaras1/.venv/lib/python3.10/site-packages/tornado/ioloop.py", line 765, in _discard_future_result
    future.result()
  File "/home/shankaras1/.venv/lib/python3.10/site-packages/distributed/worker.py", line 1207, in heartbeat
    raise e
  File "/home/shankaras1/.venv/lib/python3.10/site-packages/distributed/worker.py", line 1161, in heartbeat
    response = await retry_operation(
  File "/home/shankaras1/.venv/lib/python3.10/site-packages/distributed/utils_comm.py", line 383, in retry_operation
    return await retry(
  File "/home/shankaras1/.venv/lib/python3.10/site-packages/distributed/utils_comm.py", line 368, in retry
    return await coro()
  File "/home/shankaras1/.venv/lib/python3.10/site-packages/distributed/core.py", line 1150, in send_recv_from_rpc
    comm = await self.pool.connect(self.addr)
  File "/home/shankaras1/.venv/lib/python3.10/site-packages/distributed/core.py", line 1371, in connect
    return await connect_attempt
  File "/home/shankaras1/.venv/lib/python3.10/site-packages/distributed/core.py", line 1307, in _connect
    comm = await connect(
  File "/home/shankaras1/.venv/lib/python3.10/site-packages/distributed/comm/core.py", line 333, in connect
    raise OSError(
OSError: Timed out during handshake while connecting to tcp://127.0.0.1:39719 after 30 s
omega = 1.79508e-06 finished in 39.01165553598548 seconds.
omega = 3.19277e-06 finished in 39.99351027197554 seconds.
2024-05-09 22:09:30,281 - distributed.nanny - ERROR - Worker process died unexpectedly
omega = 5.68309e-05 finished in 39.94130751598277 seconds.
omega = 5.67873e-06 finished in 40.21286910600611 seconds.
2024-05-09 22:09:30,682 - distributed.worker - ERROR - Timed out during handshake while connecting to tcp://127.0.0.1:39719 after 30 s
Traceback (most recent call last):
  File "/home/shankaras1/.venv/lib/python3.10/site-packages/distributed/comm/tcp.py", line 264, in write
    async def write(self, msg, serializers=None, on_error="message"):
asyncio.exceptions.CancelledError

During handling of the above exception, another exception occurred:

Traceback (most recent call last):
  File "/easybuild/software/Python/3.10.8-GCCcore-12.2.0/lib/python3.10/asyncio/tasks.py", line 418, in wait_for
    return fut.result()
asyncio.exceptions.CancelledError

The above exception was the direct cause of the following exception:

Traceback (most recent call last):
  File "/home/shankaras1/.venv/lib/python3.10/site-packages/distributed/comm/core.py", line 329, in connect
    await asyncio.wait_for(comm.write(local_info), time_left())
  File "/easybuild/software/Python/3.10.8-GCCcore-12.2.0/lib/python3.10/asyncio/tasks.py", line 420, in wait_for
    raise exceptions.TimeoutError() from exc
asyncio.exceptions.TimeoutError

The above exception was the direct cause of the following exception:

Traceback (most recent call last):
  File "/home/shankaras1/.venv/lib/python3.10/site-packages/distributed/worker.py", line 1161, in heartbeat
    response = await retry_operation(
  File "/home/shankaras1/.venv/lib/python3.10/site-packages/distributed/utils_comm.py", line 383, in retry_operation
    return await retry(
  File "/home/shankaras1/.venv/lib/python3.10/site-packages/distributed/utils_comm.py", line 368, in retry
    return await coro()
  File "/home/shankaras1/.venv/lib/python3.10/site-packages/distributed/core.py", line 1150, in send_recv_from_rpc
    comm = await self.pool.connect(self.addr)
  File "/home/shankaras1/.venv/lib/python3.10/site-packages/distributed/core.py", line 1371, in connect
    return await connect_attempt
  File "/home/shankaras1/.venv/lib/python3.10/site-packages/distributed/core.py", line 1307, in _connect
    comm = await connect(
  File "/home/shankaras1/.venv/lib/python3.10/site-packages/distributed/comm/core.py", line 333, in connect
    raise OSError(
OSError: Timed out during handshake while connecting to tcp://127.0.0.1:39719 after 30 s
omega = 1.95928e-06 entered
2024-05-09 22:09:30,684 - tornado.application - ERROR - Exception in callback functools.partial(<bound method IOLoop._discard_future_result of <tornado.platform.asyncio.AsyncIOLoop object at 0x155548c28b20>>, <Task finished name='Task-33' coro=<Worker.heartbeat() done, defined at /home/shankaras1/.venv/lib/python3.10/site-packages/distributed/worker.py:1153> exception=OSError('Timed out during handshake while connecting to tcp://127.0.0.1:39719 after 30 s')>)
Traceback (most recent call last):
  File "/home/shankaras1/.venv/lib/python3.10/site-packages/distributed/comm/tcp.py", line 264, in write
    async def write(self, msg, serializers=None, on_error="message"):
asyncio.exceptions.CancelledError

During handling of the above exception, another exception occurred:

Traceback (most recent call last):
  File "/easybuild/software/Python/3.10.8-GCCcore-12.2.0/lib/python3.10/asyncio/tasks.py", line 418, in wait_for
    return fut.result()
asyncio.exceptions.CancelledError

The above exception was the direct cause of the following exception:

Traceback (most recent call last):
  File "/home/shankaras1/.venv/lib/python3.10/site-packages/distributed/comm/core.py", line 329, in connect
    await asyncio.wait_for(comm.write(local_info), time_left())
  File "/easybuild/software/Python/3.10.8-GCCcore-12.2.0/lib/python3.10/asyncio/tasks.py", line 420, in wait_for
    raise exceptions.TimeoutError() from exc
asyncio.exceptions.TimeoutError

The above exception was the direct cause of the following exception:

Traceback (most recent call last):
  File "/home/shankaras1/.venv/lib/python3.10/site-packages/tornado/ioloop.py", line 741, in _run_callback
    ret = callback()
  File "/home/shankaras1/.venv/lib/python3.10/site-packages/tornado/ioloop.py", line 765, in _discard_future_result
    future.result()
  File "/home/shankaras1/.venv/lib/python3.10/site-packages/distributed/worker.py", line 1207, in heartbeat
    raise e
  File "/home/shankaras1/.venv/lib/python3.10/site-packages/distributed/worker.py", line 1161, in heartbeat
    response = await retry_operation(
  File "/home/shankaras1/.venv/lib/python3.10/site-packages/distributed/utils_comm.py", line 383, in retry_operation
    return await retry(
  File "/home/shankaras1/.venv/lib/python3.10/site-packages/distributed/utils_comm.py", line 368, in retry
    return await coro()
  File "/home/shankaras1/.venv/lib/python3.10/site-packages/distributed/core.py", line 1150, in send_recv_from_rpc
    comm = await self.pool.connect(self.addr)
  File "/home/shankaras1/.venv/lib/python3.10/site-packages/distributed/core.py", line 1371, in connect
    return await connect_attempt
  File "/home/shankaras1/.venv/lib/python3.10/site-packages/distributed/core.py", line 1307, in _connect
    comm = await connect(
  File "/home/shankaras1/.venv/lib/python3.10/site-packages/distributed/comm/core.py", line 333, in connect
    raise OSError(
OSError: Timed out during handshake while connecting to tcp://127.0.0.1:39719 after 30 s
omega = 1.01003e-05 finished in 40.88209754100535 seconds.
2024-05-09 22:09:32,536 - distributed.worker - ERROR - Timed out during handshake while connecting to tcp://127.0.0.1:39719 after 30 s
Traceback (most recent call last):
  File "/home/shankaras1/.venv/lib/python3.10/site-packages/distributed/comm/tcp.py", line 264, in write
    async def write(self, msg, serializers=None, on_error="message"):
asyncio.exceptions.CancelledError

During handling of the above exception, another exception occurred:

Traceback (most recent call last):
  File "/easybuild/software/Python/3.10.8-GCCcore-12.2.0/lib/python3.10/asyncio/tasks.py", line 418, in wait_for
    return fut.result()
asyncio.exceptions.CancelledError

The above exception was the direct cause of the following exception:

Traceback (most recent call last):
  File "/home/shankaras1/.venv/lib/python3.10/site-packages/distributed/comm/core.py", line 329, in connect
    await asyncio.wait_for(comm.write(local_info), time_left())
  File "/easybuild/software/Python/3.10.8-GCCcore-12.2.0/lib/python3.10/asyncio/tasks.py", line 420, in wait_for
    raise exceptions.TimeoutError() from exc
asyncio.exceptions.TimeoutError

The above exception was the direct cause of the following exception:

Traceback (most recent call last):
  File "/home/shankaras1/.venv/lib/python3.10/site-packages/distributed/worker.py", line 1161, in heartbeat
    response = await retry_operation(
  File "/home/shankaras1/.venv/lib/python3.10/site-packages/distributed/utils_comm.py", line 383, in retry_operation
    return await retry(
  File "/home/shankaras1/.venv/lib/python3.10/site-packages/distributed/utils_comm.py", line 368, in retry
    return await coro()
  File "/home/shankaras1/.venv/lib/python3.10/site-packages/distributed/core.py", line 1150, in send_recv_from_rpc
    comm = await self.pool.connect(self.addr)
  File "/home/shankaras1/.venv/lib/python3.10/site-packages/distributed/core.py", line 1371, in connect
    return await connect_attempt
  File "/home/shankaras1/.venv/lib/python3.10/site-packages/distributed/core.py", line 1307, in _connect
    comm = await connect(
  File "/home/shankaras1/.venv/lib/python3.10/site-packages/distributed/comm/core.py", line 333, in connect
    raise OSError(
OSError: Timed out during handshake while connecting to tcp://127.0.0.1:39719 after 30 s
2024-05-09 22:09:32,539 - tornado.application - ERROR - Exception in callback functools.partial(<bound method IOLoop._discard_future_result of <tornado.platform.asyncio.AsyncIOLoop object at 0x155548c28b20>>, <Task finished name='Task-34' coro=<Worker.heartbeat() done, defined at /home/shankaras1/.venv/lib/python3.10/site-packages/distributed/worker.py:1153> exception=OSError('Timed out during handshake while connecting to tcp://127.0.0.1:39719 after 30 s')>)
Traceback (most recent call last):
  File "/home/shankaras1/.venv/lib/python3.10/site-packages/distributed/comm/tcp.py", line 264, in write
    async def write(self, msg, serializers=None, on_error="message"):
asyncio.exceptions.CancelledError

During handling of the above exception, another exception occurred:

Traceback (most recent call last):
  File "/easybuild/software/Python/3.10.8-GCCcore-12.2.0/lib/python3.10/asyncio/tasks.py", line 418, in wait_for
    return fut.result()
asyncio.exceptions.CancelledError

The above exception was the direct cause of the following exception:

Traceback (most recent call last):
  File "/home/shankaras1/.venv/lib/python3.10/site-packages/distributed/comm/core.py", line 329, in connect
    await asyncio.wait_for(comm.write(local_info), time_left())
  File "/easybuild/software/Python/3.10.8-GCCcore-12.2.0/lib/python3.10/asyncio/tasks.py", line 420, in wait_for
    raise exceptions.TimeoutError() from exc
asyncio.exceptions.TimeoutError

The above exception was the direct cause of the following exception:

Traceback (most recent call last):
  File "/home/shankaras1/.venv/lib/python3.10/site-packages/tornado/ioloop.py", line 741, in _run_callback
    ret = callback()
  File "/home/shankaras1/.venv/lib/python3.10/site-packages/tornado/ioloop.py", line 765, in _discard_future_result
    future.result()
  File "/home/shankaras1/.venv/lib/python3.10/site-packages/distributed/worker.py", line 1207, in heartbeat
    raise e
  File "/home/shankaras1/.venv/lib/python3.10/site-packages/distributed/worker.py", line 1161, in heartbeat
    response = await retry_operation(
  File "/home/shankaras1/.venv/lib/python3.10/site-packages/distributed/utils_comm.py", line 383, in retry_operation
    return await retry(
  File "/home/shankaras1/.venv/lib/python3.10/site-packages/distributed/utils_comm.py", line 368, in retry
    return await coro()
  File "/home/shankaras1/.venv/lib/python3.10/site-packages/distributed/core.py", line 1150, in send_recv_from_rpc
    comm = await self.pool.connect(self.addr)
  File "/home/shankaras1/.venv/lib/python3.10/site-packages/distributed/core.py", line 1371, in connect
    return await connect_attempt
  File "/home/shankaras1/.venv/lib/python3.10/site-packages/distributed/core.py", line 1307, in _connect
    comm = await connect(
  File "/home/shankaras1/.venv/lib/python3.10/site-packages/distributed/comm/core.py", line 333, in connect
    raise OSError(
OSError: Timed out during handshake while connecting to tcp://127.0.0.1:39719 after 30 s
omega = 1.94132e-06 entered
omega = 0.000101081 finished in 41.09827174298698 seconds.
omega = 1.95028e-06 entered
2024-05-09 22:09:33,527 - distributed.worker - ERROR - Timed out during handshake while connecting to tcp://127.0.0.1:39719 after 30 s
Traceback (most recent call last):
  File "/home/shankaras1/.venv/lib/python3.10/site-packages/distributed/comm/tcp.py", line 264, in write
    async def write(self, msg, serializers=None, on_error="message"):
asyncio.exceptions.CancelledError

During handling of the above exception, another exception occurred:

Traceback (most recent call last):
  File "/easybuild/software/Python/3.10.8-GCCcore-12.2.0/lib/python3.10/asyncio/tasks.py", line 418, in wait_for
    return fut.result()
asyncio.exceptions.CancelledError

The above exception was the direct cause of the following exception:

Traceback (most recent call last):
  File "/home/shankaras1/.venv/lib/python3.10/site-packages/distributed/comm/core.py", line 329, in connect
    await asyncio.wait_for(comm.write(local_info), time_left())
  File "/easybuild/software/Python/3.10.8-GCCcore-12.2.0/lib/python3.10/asyncio/tasks.py", line 420, in wait_for
    raise exceptions.TimeoutError() from exc
asyncio.exceptions.TimeoutError

The above exception was the direct cause of the following exception:

Traceback (most recent call last):
  File "/home/shankaras1/.venv/lib/python3.10/site-packages/distributed/worker.py", line 1161, in heartbeat
    response = await retry_operation(
  File "/home/shankaras1/.venv/lib/python3.10/site-packages/distributed/utils_comm.py", line 383, in retry_operation
    return await retry(
  File "/home/shankaras1/.venv/lib/python3.10/site-packages/distributed/utils_comm.py", line 368, in retry
    return await coro()
  File "/home/shankaras1/.venv/lib/python3.10/site-packages/distributed/core.py", line 1150, in send_recv_from_rpc
    comm = await self.pool.connect(self.addr)
  File "/home/shankaras1/.venv/lib/python3.10/site-packages/distributed/core.py", line 1371, in connect
    return await connect_attempt
  File "/home/shankaras1/.venv/lib/python3.10/site-packages/distributed/core.py", line 1307, in _connect
    comm = await connect(
  File "/home/shankaras1/.venv/lib/python3.10/site-packages/distributed/comm/core.py", line 333, in connect
    raise OSError(
OSError: Timed out during handshake while connecting to tcp://127.0.0.1:39719 after 30 s
omega = 1.79646e-05 finished in 41.18156934299623 seconds.
omega = 1.97742e-06 entered
omega = 0.000319768 finished in 40.27544555597706 seconds.
omega = 1.82006e-06 entered
2024-05-09 22:09:33,670 - tornado.application - ERROR - Exception in callback functools.partial(<bound method IOLoop._discard_future_result of <tornado.platform.asyncio.AsyncIOLoop object at 0x155548c28b20>>, <Task finished name='Task-33' coro=<Worker.heartbeat() done, defined at /home/shankaras1/.venv/lib/python3.10/site-packages/distributed/worker.py:1153> exception=OSError('Timed out during handshake while connecting to tcp://127.0.0.1:39719 after 30 s')>)
Traceback (most recent call last):
  File "/home/shankaras1/.venv/lib/python3.10/site-packages/distributed/comm/tcp.py", line 264, in write
    async def write(self, msg, serializers=None, on_error="message"):
asyncio.exceptions.CancelledError

During handling of the above exception, another exception occurred:

Traceback (most recent call last):
  File "/easybuild/software/Python/3.10.8-GCCcore-12.2.0/lib/python3.10/asyncio/tasks.py", line 418, in wait_for
    return fut.result()
asyncio.exceptions.CancelledError

The above exception was the direct cause of the following exception:

Traceback (most recent call last):
  File "/home/shankaras1/.venv/lib/python3.10/site-packages/distributed/comm/core.py", line 329, in connect
    await asyncio.wait_for(comm.write(local_info), time_left())
  File "/easybuild/software/Python/3.10.8-GCCcore-12.2.0/lib/python3.10/asyncio/tasks.py", line 420, in wait_for
    raise exceptions.TimeoutError() from exc
asyncio.exceptions.TimeoutError

The above exception was the direct cause of the following exception:

Traceback (most recent call last):
  File "/home/shankaras1/.venv/lib/python3.10/site-packages/tornado/ioloop.py", line 741, in _run_callback
    ret = callback()
  File "/home/shankaras1/.venv/lib/python3.10/site-packages/tornado/ioloop.py", line 765, in _discard_future_result
    future.result()
  File "/home/shankaras1/.venv/lib/python3.10/site-packages/distributed/worker.py", line 1207, in heartbeat
    raise e
  File "/home/shankaras1/.venv/lib/python3.10/site-packages/distributed/worker.py", line 1161, in heartbeat
    response = await retry_operation(
  File "/home/shankaras1/.venv/lib/python3.10/site-packages/distributed/utils_comm.py", line 383, in retry_operation
    return await retry(
  File "/home/shankaras1/.venv/lib/python3.10/site-packages/distributed/utils_comm.py", line 368, in retry
    return await coro()
  File "/home/shankaras1/.venv/lib/python3.10/site-packages/distributed/core.py", line 1150, in send_recv_from_rpc
    comm = await self.pool.connect(self.addr)
  File "/home/shankaras1/.venv/lib/python3.10/site-packages/distributed/core.py", line 1371, in connect
    return await connect_attempt
  File "/home/shankaras1/.venv/lib/python3.10/site-packages/distributed/core.py", line 1307, in _connect
    comm = await connect(
  File "/home/shankaras1/.venv/lib/python3.10/site-packages/distributed/comm/core.py", line 333, in connect
    raise OSError(
OSError: Timed out during handshake while connecting to tcp://127.0.0.1:39719 after 30 s
omega = 1.00926e-06 finished in 41.72463344599237 seconds.
omega = 1.01392e-06 entered
omega = 3.19523e-05 finished in 41.82251181799802 seconds.
2024-05-09 22:09:37,431 - distributed.worker - ERROR - Timed out during handshake while connecting to tcp://127.0.0.1:39719 after 30 s
Traceback (most recent call last):
  File "/home/shankaras1/.venv/lib/python3.10/site-packages/distributed/comm/tcp.py", line 214, in read
    async def read(self, deserializers=None):
asyncio.exceptions.CancelledError

During handling of the above exception, another exception occurred:

Traceback (most recent call last):
  File "/easybuild/software/Python/3.10.8-GCCcore-12.2.0/lib/python3.10/asyncio/tasks.py", line 418, in wait_for
    return fut.result()
asyncio.exceptions.CancelledError

The above exception was the direct cause of the following exception:

Traceback (most recent call last):
  File "/home/shankaras1/.venv/lib/python3.10/site-packages/distributed/comm/core.py", line 328, in connect
    handshake = await asyncio.wait_for(comm.read(), time_left())
  File "/easybuild/software/Python/3.10.8-GCCcore-12.2.0/lib/python3.10/asyncio/tasks.py", line 420, in wait_for
    raise exceptions.TimeoutError() from exc
asyncio.exceptions.TimeoutError

The above exception was the direct cause of the following exception:

Traceback (most recent call last):
  File "/home/shankaras1/.venv/lib/python3.10/site-packages/distributed/worker.py", line 1161, in heartbeat
    response = await retry_operation(
  File "/home/shankaras1/.venv/lib/python3.10/site-packages/distributed/utils_comm.py", line 383, in retry_operation
    return await retry(
  File "/home/shankaras1/.venv/lib/python3.10/site-packages/distributed/utils_comm.py", line 368, in retry
    return await coro()
  File "/home/shankaras1/.venv/lib/python3.10/site-packages/distributed/core.py", line 1150, in send_recv_from_rpc
    comm = await self.pool.connect(self.addr)
  File "/home/shankaras1/.venv/lib/python3.10/site-packages/distributed/core.py", line 1371, in connect
    return await connect_attempt
  File "/home/shankaras1/.venv/lib/python3.10/site-packages/distributed/core.py", line 1307, in _connect
    comm = await connect(
  File "/home/shankaras1/.venv/lib/python3.10/site-packages/distributed/comm/core.py", line 333, in connect
    raise OSError(
OSError: Timed out during handshake while connecting to tcp://127.0.0.1:39719 after 30 s
2024-05-09 22:09:37,434 - tornado.application - ERROR - Exception in callback functools.partial(<bound method IOLoop._discard_future_result of <tornado.platform.asyncio.AsyncIOLoop object at 0x155548c28b20>>, <Task finished name='Task-32' coro=<Worker.heartbeat() done, defined at /home/shankaras1/.venv/lib/python3.10/site-packages/distributed/worker.py:1153> exception=OSError('Timed out during handshake while connecting to tcp://127.0.0.1:39719 after 30 s')>)
Traceback (most recent call last):
  File "/home/shankaras1/.venv/lib/python3.10/site-packages/distributed/comm/tcp.py", line 214, in read
    async def read(self, deserializers=None):
asyncio.exceptions.CancelledError

During handling of the above exception, another exception occurred:

Traceback (most recent call last):
  File "/easybuild/software/Python/3.10.8-GCCcore-12.2.0/lib/python3.10/asyncio/tasks.py", line 418, in wait_for
    return fut.result()
asyncio.exceptions.CancelledError

The above exception was the direct cause of the following exception:

Traceback (most recent call last):
  File "/home/shankaras1/.venv/lib/python3.10/site-packages/distributed/comm/core.py", line 328, in connect
    handshake = await asyncio.wait_for(comm.read(), time_left())
  File "/easybuild/software/Python/3.10.8-GCCcore-12.2.0/lib/python3.10/asyncio/tasks.py", line 420, in wait_for
    raise exceptions.TimeoutError() from exc
asyncio.exceptions.TimeoutError

The above exception was the direct cause of the following exception:

Traceback (most recent call last):
  File "/home/shankaras1/.venv/lib/python3.10/site-packages/tornado/ioloop.py", line 741, in _run_callback
    ret = callback()
  File "/home/shankaras1/.venv/lib/python3.10/site-packages/tornado/ioloop.py", line 765, in _discard_future_result
    future.result()
  File "/home/shankaras1/.venv/lib/python3.10/site-packages/distributed/worker.py", line 1207, in heartbeat
    raise e
  File "/home/shankaras1/.venv/lib/python3.10/site-packages/distributed/worker.py", line 1161, in heartbeat
    response = await retry_operation(
  File "/home/shankaras1/.venv/lib/python3.10/site-packages/distributed/utils_comm.py", line 383, in retry_operation
    return await retry(
  File "/home/shankaras1/.venv/lib/python3.10/site-packages/distributed/utils_comm.py", line 368, in retry
    return await coro()
  File "/home/shankaras1/.venv/lib/python3.10/site-packages/distributed/core.py", line 1150, in send_recv_from_rpc
    comm = await self.pool.connect(self.addr)
  File "/home/shankaras1/.venv/lib/python3.10/site-packages/distributed/core.py", line 1371, in connect
    return await connect_attempt
  File "/home/shankaras1/.venv/lib/python3.10/site-packages/distributed/core.py", line 1307, in _connect
    comm = await connect(
  File "/home/shankaras1/.venv/lib/python3.10/site-packages/distributed/comm/core.py", line 333, in connect
    raise OSError(
OSError: Timed out during handshake while connecting to tcp://127.0.0.1:39719 after 30 s
omega = 1.96833e-06 entered
omega = 0.000179784 finished in 42.55321856099181 seconds.
2024-05-09 22:09:37,952 - distributed.nanny - ERROR - Worker process died unexpectedly
omega = 0.000568746 finished in 42.855423126980895 seconds.
2024-05-09 22:09:39,471 - distributed.worker - ERROR - Timed out during handshake while connecting to tcp://127.0.0.1:39719 after 30 s
Traceback (most recent call last):
  File "/home/shankaras1/.venv/lib/python3.10/site-packages/distributed/comm/tcp.py", line 264, in write
    async def write(self, msg, serializers=None, on_error="message"):
asyncio.exceptions.CancelledError

During handling of the above exception, another exception occurred:

Traceback (most recent call last):
  File "/easybuild/software/Python/3.10.8-GCCcore-12.2.0/lib/python3.10/asyncio/tasks.py", line 418, in wait_for
    return fut.result()
asyncio.exceptions.CancelledError

The above exception was the direct cause of the following exception:

Traceback (most recent call last):
  File "/home/shankaras1/.venv/lib/python3.10/site-packages/distributed/comm/core.py", line 329, in connect
    await asyncio.wait_for(comm.write(local_info), time_left())
  File "/easybuild/software/Python/3.10.8-GCCcore-12.2.0/lib/python3.10/asyncio/tasks.py", line 420, in wait_for
    raise exceptions.TimeoutError() from exc
asyncio.exceptions.TimeoutError

The above exception was the direct cause of the following exception:

Traceback (most recent call last):
  File "/home/shankaras1/.venv/lib/python3.10/site-packages/distributed/worker.py", line 1161, in heartbeat
    response = await retry_operation(
  File "/home/shankaras1/.venv/lib/python3.10/site-packages/distributed/utils_comm.py", line 383, in retry_operation
    return await retry(
  File "/home/shankaras1/.venv/lib/python3.10/site-packages/distributed/utils_comm.py", line 368, in retry
    return await coro()
  File "/home/shankaras1/.venv/lib/python3.10/site-packages/distributed/core.py", line 1150, in send_recv_from_rpc
    comm = await self.pool.connect(self.addr)
  File "/home/shankaras1/.venv/lib/python3.10/site-packages/distributed/core.py", line 1371, in connect
    return await connect_attempt
  File "/home/shankaras1/.venv/lib/python3.10/site-packages/distributed/core.py", line 1307, in _connect
    comm = await connect(
  File "/home/shankaras1/.venv/lib/python3.10/site-packages/distributed/comm/core.py", line 333, in connect
    raise OSError(
OSError: Timed out during handshake while connecting to tcp://127.0.0.1:39719 after 30 s
omega = 1.8117e-06 entered
2024-05-09 22:09:39,473 - tornado.application - ERROR - Exception in callback functools.partial(<bound method IOLoop._discard_future_result of <tornado.platform.asyncio.AsyncIOLoop object at 0x155548c28b20>>, <Task finished name='Task-35' coro=<Worker.heartbeat() done, defined at /home/shankaras1/.venv/lib/python3.10/site-packages/distributed/worker.py:1153> exception=OSError('Timed out during handshake while connecting to tcp://127.0.0.1:39719 after 30 s')>)
Traceback (most recent call last):
  File "/home/shankaras1/.venv/lib/python3.10/site-packages/distributed/comm/tcp.py", line 264, in write
    async def write(self, msg, serializers=None, on_error="message"):
asyncio.exceptions.CancelledError

During handling of the above exception, another exception occurred:

Traceback (most recent call last):
  File "/easybuild/software/Python/3.10.8-GCCcore-12.2.0/lib/python3.10/asyncio/tasks.py", line 418, in wait_for
    return fut.result()
asyncio.exceptions.CancelledError

The above exception was the direct cause of the following exception:

Traceback (most recent call last):
  File "/home/shankaras1/.venv/lib/python3.10/site-packages/distributed/comm/core.py", line 329, in connect
    await asyncio.wait_for(comm.write(local_info), time_left())
  File "/easybuild/software/Python/3.10.8-GCCcore-12.2.0/lib/python3.10/asyncio/tasks.py", line 420, in wait_for
    raise exceptions.TimeoutError() from exc
asyncio.exceptions.TimeoutError

The above exception was the direct cause of the following exception:

Traceback (most recent call last):
  File "/home/shankaras1/.venv/lib/python3.10/site-packages/tornado/ioloop.py", line 741, in _run_callback
    ret = callback()
  File "/home/shankaras1/.venv/lib/python3.10/site-packages/tornado/ioloop.py", line 765, in _discard_future_result
    future.result()
  File "/home/shankaras1/.venv/lib/python3.10/site-packages/distributed/worker.py", line 1207, in heartbeat
    raise e
  File "/home/shankaras1/.venv/lib/python3.10/site-packages/distributed/worker.py", line 1161, in heartbeat
    response = await retry_operation(
  File "/home/shankaras1/.venv/lib/python3.10/site-packages/distributed/utils_comm.py", line 383, in retry_operation
    return await retry(
  File "/home/shankaras1/.venv/lib/python3.10/site-packages/distributed/utils_comm.py", line 368, in retry
    return await coro()
  File "/home/shankaras1/.venv/lib/python3.10/site-packages/distributed/core.py", line 1150, in send_recv_from_rpc
    comm = await self.pool.connect(self.addr)
  File "/home/shankaras1/.venv/lib/python3.10/site-packages/distributed/core.py", line 1371, in connect
    return await connect_attempt
  File "/home/shankaras1/.venv/lib/python3.10/site-packages/distributed/core.py", line 1307, in _connect
    comm = await connect(
  File "/home/shankaras1/.venv/lib/python3.10/site-packages/distributed/comm/core.py", line 333, in connect
    raise OSError(
OSError: Timed out during handshake while connecting to tcp://127.0.0.1:39719 after 30 s
omega = 0.00571811 finished in 33.467635043984046 seconds.
omega = 1.88839e-06 entered
omega = 0.0180892 finished in 33.923774268012494 seconds.
omega = 1.80337e-06 entered
omega = 0.181031 finished in 33.590836543007754 seconds.
omega = 1.86247e-06 entered
omega = 0.00101625 finished in 34.1087340300146 seconds.
omega = 1.84539e-06 entered
omega = 0.0321738 finished in 33.23674903900246 seconds.
omega = 1.78683e-06 entered
omega = 0.00180753 finished in 34.459824778023176 seconds.
omega = 1.77862e-06 entered
omega = 0.00321491 finished in 34.51826345300651 seconds.
omega = 1.79508e-06 entered
omega = 0.057225 finished in 33.96326704000239 seconds.
omega = 1.87107e-06 entered
omega = 0.101782 finished in 34.53427019700757 seconds.
omega = 1.85391e-06 entered
omega = 0.0101703 finished in 33.51055437701871 seconds.
omega = 0.321985 finished in 33.82953894001548 seconds.
omega = 1.87971e-06 entered
omega = 0.57269 finished in 37.83710047099157 seconds.
omega = 1.83691e-06 entered
omega = 1.95928e-06 finished in 37.71939878500416 seconds.
omega = 2.16826e-06 entered
/data1/shankaras1/python_files/BLG/v3_RGF_BBG.py:235: IntegrationWarning: The integral is probably divergent, or slowly convergent.
  intlist = [quad(call_int,window[0],window[1],limit=200,epsabs=delta)[0] for window in ranges]
omega = 1.95028e-06 finished in 37.63190371499513 seconds.
omega = 2.1583e-06 entered
omega = 1.82006e-06 finished in 37.89185958899907 seconds.
omega = 2.01419e-06 entered
omega = 1.94132e-06 finished in 39.54748754002503 seconds.
2024-05-09 22:10:12,107 - distributed.nanny - ERROR - Worker process died unexpectedly
omega = 1.97742e-06 finished in 38.212260820000665 seconds.
omega = 2.18833e-06 entered
omega = 1.01392e-06 finished in 38.22890248999465 seconds.
omega = 1.0186e-06 entered
omega = 1.96833e-06 finished in 37.59571844100719 seconds.
omega = 2.17827e-06 entered
/data1/shankaras1/python_files/BLG/v3_RGF_BBG.py:235: IntegrationWarning: The integral is probably divergent, or slowly convergent.
  intlist = [quad(call_int,window[0],window[1],limit=200,epsabs=delta)[0] for window in ranges]
omega = 1.8117e-06 finished in 37.83515431298292 seconds.
omega = 2.00494e-06 entered
/data1/shankaras1/python_files/BLG/v3_RGF_BBG.py:235: IntegrationWarning: The integral is probably divergent, or slowly convergent.
  intlist = [quad(call_int,window[0],window[1],limit=200,epsabs=delta)[0] for window in ranges]
/data1/shankaras1/python_files/BLG/v3_RGF_BBG.py:235: IntegrationWarning: The integral is probably divergent, or slowly convergent.
  intlist = [quad(call_int,window[0],window[1],limit=200,epsabs=delta)[0] for window in ranges]
/data1/shankaras1/python_files/BLG/v3_RGF_BBG.py:235: IntegrationWarning: The integral is probably divergent, or slowly convergent.
  intlist = [quad(call_int,window[0],window[1],limit=200,epsabs=delta)[0] for window in ranges]
/data1/shankaras1/python_files/BLG/v3_RGF_BBG.py:235: IntegrationWarning: The integral is probably divergent, or slowly convergent.
  intlist = [quad(call_int,window[0],window[1],limit=200,epsabs=delta)[0] for window in ranges]
/data1/shankaras1/python_files/BLG/v3_RGF_BBG.py:235: IntegrationWarning: The integral is probably divergent, or slowly convergent.
  intlist = [quad(call_int,window[0],window[1],limit=200,epsabs=delta)[0] for window in ranges]
/data1/shankaras1/python_files/BLG/v3_RGF_BBG.py:235: IntegrationWarning: The integral is probably divergent, or slowly convergent.
  intlist = [quad(call_int,window[0],window[1],limit=200,epsabs=delta)[0] for window in ranges]
/data1/shankaras1/python_files/BLG/v3_RGF_BBG.py:235: IntegrationWarning: The integral is probably divergent, or slowly convergent.
  intlist = [quad(call_int,window[0],window[1],limit=200,epsabs=delta)[0] for window in ranges]
/data1/shankaras1/python_files/BLG/v3_RGF_BBG.py:235: IntegrationWarning: The integral is probably divergent, or slowly convergent.
  intlist = [quad(call_int,window[0],window[1],limit=200,epsabs=delta)[0] for window in ranges]
/data1/shankaras1/python_files/BLG/v3_RGF_BBG.py:235: IntegrationWarning: The integral is probably divergent, or slowly convergent.
  intlist = [quad(call_int,window[0],window[1],limit=200,epsabs=delta)[0] for window in ranges]
omega = 1.88839e-06 finished in 37.521067716996185 seconds.
2024-05-09 22:10:23,366 - distributed.nanny - ERROR - Worker process died unexpectedly
omega = 1.86247e-06 finished in 37.62672816897975 seconds.
omega = 2.06113e-06 entered
omega = 1.80337e-06 finished in 38.19761350098997 seconds.
omega = 1.89711e-06 entered
omega = 1.84539e-06 finished in 37.94120407899027 seconds.
omega = 2.04222e-06 entered
omega = 1.78683e-06 finished in 37.88432358999853 seconds.
omega = 1.91467e-06 entered
omega = 1.77862e-06 finished in 37.67178724799305 seconds.
omega = 1.90587e-06 entered
omega = 1.79508e-06 finished in 37.620533160021296 seconds.
omega = 1.87107e-06 finished in 37.65641825800412 seconds.
2024-05-09 22:10:26,535 - distributed.nanny - ERROR - Worker process died unexpectedly
omega = 1.85391e-06 finished in 37.75912942702416 seconds.
omega = 1.93239e-06 entered
omega = 1.87971e-06 finished in 37.70094936501118 seconds.
omega = 2.0802e-06 entered
/data1/shankaras1/python_files/BLG/v3_RGF_BBG.py:235: IntegrationWarning: The integral is probably divergent, or slowly convergent.
  intlist = [quad(call_int,window[0],window[1],limit=200,epsabs=delta)[0] for window in ranges]
omega = 1.83691e-06 finished in 36.98171148102847 seconds.
omega = 2.03284e-06 entered
omega = 2.16826e-06 finished in 37.11172507100855 seconds.
Traceback (most recent call last):
  File "/data1/shankaras1/python_files/BLG/v3_RGF_BBG.py", line 307, in <module>
    dask_LDOS()
  File "/data1/shankaras1/python_files/BLG/v3_RGF_BBG.py", line 255, in dask_LDOS
    LDOS = client.gather(client.map(helper_LDOS_mp,omegavals))
  File "/home/shankaras1/.venv/lib/python3.10/site-packages/distributed/client.py", line 2174, in gather
    return self.sync(
  File "/home/shankaras1/.venv/lib/python3.10/site-packages/distributed/utils.py", line 338, in sync
    return sync(
  File "/home/shankaras1/.venv/lib/python3.10/site-packages/distributed/utils.py", line 405, in sync
    raise exc.with_traceback(tb)
  File "/home/shankaras1/.venv/lib/python3.10/site-packages/distributed/utils.py", line 378, in f
    result = yield future
  File "/home/shankaras1/.venv/lib/python3.10/site-packages/tornado/gen.py", line 762, in run
    value = future.result()
  File "/home/shankaras1/.venv/lib/python3.10/site-packages/distributed/client.py", line 2037, in _gather
    raise exception.with_traceback(traceback)
distributed.scheduler.KilledWorker: ('helper_LDOS_mp-764870b42fa226c87898e557ed0b405d', <WorkerState 'tcp://127.0.0.1:34113', name: 8, status: closed, memory: 0, processing: 195>)
omega = 2.1583e-06 finished in 37.61474813200766 seconds.
omega = 2.01419e-06 finished in 37.0293176319974 seconds.
2024-05-09 22:10:49,586 - distributed.nanny - WARNING - Worker process still alive after 3.9999994277954105 seconds, killing
2024-05-09 22:10:49,587 - distributed.nanny - WARNING - Worker process still alive after 3.9999994277954105 seconds, killing
2024-05-09 22:10:49,587 - distributed.nanny - WARNING - Worker process still alive after 3.9999996185302735 seconds, killing
2024-05-09 22:10:49,588 - distributed.nanny - WARNING - Worker process still alive after 3.999999237060547 seconds, killing
2024-05-09 22:10:49,588 - distributed.nanny - WARNING - Worker process still alive after 3.999999237060547 seconds, killing
2024-05-09 22:10:49,589 - distributed.nanny - WARNING - Worker process still alive after 3.9999994277954105 seconds, killing
2024-05-09 22:10:49,589 - distributed.nanny - WARNING - Worker process still alive after 3.9999994277954105 seconds, killing
2024-05-09 22:10:49,590 - distributed.nanny - WARNING - Worker process still alive after 3.9999994277954105 seconds, killing
2024-05-09 22:10:49,590 - distributed.nanny - WARNING - Worker process still alive after 3.9999994277954105 seconds, killing
2024-05-09 22:10:49,591 - distributed.nanny - WARNING - Worker process still alive after 3.9999994277954105 seconds, killing
2024-05-09 22:10:49,591 - distributed.nanny - WARNING - Worker process still alive after 3.9999996185302735 seconds, killing
2024-05-09 22:10:49,592 - distributed.nanny - WARNING - Worker process still alive after 3.9999994277954105 seconds, killing
[/bin/bash]#### SLURM script finished. 
